{"cells":[{"cell_type":"code","execution_count":2,"metadata":{"colab":{"base_uri":"https://localhost:8080/"},"executionInfo":{"elapsed":6311,"status":"ok","timestamp":1719923949895,"user":{"displayName":"Pilar Raquel Hernández Galayo","userId":"08773972401991624404"},"user_tz":-120},"id":"SuKs3ewFvO2p","outputId":"75c117c8-7136-4b88-9740-d493b185efb7"},"outputs":[{"name":"stdout","output_type":"stream","text":["Requirement already satisfied: datasets in /usr/local/lib/python3.10/dist-packages (2.20.0)\n","Requirement already satisfied: filelock in /usr/local/lib/python3.10/dist-packages (from datasets) (3.15.4)\n","Requirement already satisfied: numpy\u003e=1.17 in /usr/local/lib/python3.10/dist-packages (from datasets) (1.25.2)\n","Requirement already satisfied: pyarrow\u003e=15.0.0 in /usr/local/lib/python3.10/dist-packages (from datasets) (16.1.0)\n","Requirement already satisfied: pyarrow-hotfix in /usr/local/lib/python3.10/dist-packages (from datasets) (0.6)\n","Requirement already satisfied: dill\u003c0.3.9,\u003e=0.3.0 in /usr/local/lib/python3.10/dist-packages (from datasets) (0.3.8)\n","Requirement already satisfied: pandas in /usr/local/lib/python3.10/dist-packages (from datasets) (2.0.3)\n","Requirement already satisfied: requests\u003e=2.32.2 in /usr/local/lib/python3.10/dist-packages (from datasets) (2.32.3)\n","Requirement already satisfied: tqdm\u003e=4.66.3 in /usr/local/lib/python3.10/dist-packages (from datasets) (4.66.4)\n","Requirement already satisfied: xxhash in /usr/local/lib/python3.10/dist-packages (from datasets) (3.4.1)\n","Requirement already satisfied: multiprocess in /usr/local/lib/python3.10/dist-packages (from datasets) (0.70.16)\n","Requirement already satisfied: fsspec[http]\u003c=2024.5.0,\u003e=2023.1.0 in /usr/local/lib/python3.10/dist-packages (from datasets) (2023.6.0)\n","Requirement already satisfied: aiohttp in /usr/local/lib/python3.10/dist-packages (from datasets) (3.9.5)\n","Requirement already satisfied: huggingface-hub\u003e=0.21.2 in /usr/local/lib/python3.10/dist-packages (from datasets) (0.23.4)\n","Requirement already satisfied: packaging in /usr/local/lib/python3.10/dist-packages (from datasets) (24.1)\n","Requirement already satisfied: pyyaml\u003e=5.1 in /usr/local/lib/python3.10/dist-packages (from datasets) (6.0.1)\n","Requirement already satisfied: aiosignal\u003e=1.1.2 in /usr/local/lib/python3.10/dist-packages (from aiohttp-\u003edatasets) (1.3.1)\n","Requirement already satisfied: attrs\u003e=17.3.0 in /usr/local/lib/python3.10/dist-packages (from aiohttp-\u003edatasets) (23.2.0)\n","Requirement already satisfied: frozenlist\u003e=1.1.1 in /usr/local/lib/python3.10/dist-packages (from aiohttp-\u003edatasets) (1.4.1)\n","Requirement already satisfied: multidict\u003c7.0,\u003e=4.5 in /usr/local/lib/python3.10/dist-packages (from aiohttp-\u003edatasets) (6.0.5)\n","Requirement already satisfied: yarl\u003c2.0,\u003e=1.0 in /usr/local/lib/python3.10/dist-packages (from aiohttp-\u003edatasets) (1.9.4)\n","Requirement already satisfied: async-timeout\u003c5.0,\u003e=4.0 in /usr/local/lib/python3.10/dist-packages (from aiohttp-\u003edatasets) (4.0.3)\n","Requirement already satisfied: typing-extensions\u003e=3.7.4.3 in /usr/local/lib/python3.10/dist-packages (from huggingface-hub\u003e=0.21.2-\u003edatasets) (4.12.2)\n","Requirement already satisfied: charset-normalizer\u003c4,\u003e=2 in /usr/local/lib/python3.10/dist-packages (from requests\u003e=2.32.2-\u003edatasets) (3.3.2)\n","Requirement already satisfied: idna\u003c4,\u003e=2.5 in /usr/local/lib/python3.10/dist-packages (from requests\u003e=2.32.2-\u003edatasets) (3.7)\n","Requirement already satisfied: urllib3\u003c3,\u003e=1.21.1 in /usr/local/lib/python3.10/dist-packages (from requests\u003e=2.32.2-\u003edatasets) (2.0.7)\n","Requirement already satisfied: certifi\u003e=2017.4.17 in /usr/local/lib/python3.10/dist-packages (from requests\u003e=2.32.2-\u003edatasets) (2024.6.2)\n","Requirement already satisfied: python-dateutil\u003e=2.8.2 in /usr/local/lib/python3.10/dist-packages (from pandas-\u003edatasets) (2.8.2)\n","Requirement already satisfied: pytz\u003e=2020.1 in /usr/local/lib/python3.10/dist-packages (from pandas-\u003edatasets) (2023.4)\n","Requirement already satisfied: tzdata\u003e=2022.1 in /usr/local/lib/python3.10/dist-packages (from pandas-\u003edatasets) (2024.1)\n","Requirement already satisfied: six\u003e=1.5 in /usr/local/lib/python3.10/dist-packages (from python-dateutil\u003e=2.8.2-\u003epandas-\u003edatasets) (1.16.0)\n"]}],"source":["pip install datasets"]},{"cell_type":"code","execution_count":3,"metadata":{"colab":{"base_uri":"https://localhost:8080/"},"executionInfo":{"elapsed":9013,"status":"ok","timestamp":1719923958901,"user":{"displayName":"Pilar Raquel Hernández Galayo","userId":"08773972401991624404"},"user_tz":-120},"id":"x53r72kYUIac","outputId":"4fa407f1-3ddc-47ca-9adc-da55554d43cc"},"outputs":[{"name":"stdout","output_type":"stream","text":["Requirement already satisfied: accelerate in /usr/local/lib/python3.10/dist-packages (0.31.0)\n","Requirement already satisfied: numpy\u003e=1.17 in /usr/local/lib/python3.10/dist-packages (from accelerate) (1.25.2)\n","Requirement already satisfied: packaging\u003e=20.0 in /usr/local/lib/python3.10/dist-packages (from accelerate) (24.1)\n","Requirement already satisfied: psutil in /usr/local/lib/python3.10/dist-packages (from accelerate) (5.9.5)\n","Requirement already satisfied: pyyaml in /usr/local/lib/python3.10/dist-packages (from accelerate) (6.0.1)\n","Requirement already satisfied: torch\u003e=1.10.0 in /usr/local/lib/python3.10/dist-packages (from accelerate) (2.3.0+cu121)\n","Requirement already satisfied: huggingface-hub in /usr/local/lib/python3.10/dist-packages (from accelerate) (0.23.4)\n","Requirement already satisfied: safetensors\u003e=0.3.1 in /usr/local/lib/python3.10/dist-packages (from accelerate) (0.4.3)\n","Requirement already satisfied: filelock in /usr/local/lib/python3.10/dist-packages (from torch\u003e=1.10.0-\u003eaccelerate) (3.15.4)\n","Requirement already satisfied: typing-extensions\u003e=4.8.0 in /usr/local/lib/python3.10/dist-packages (from torch\u003e=1.10.0-\u003eaccelerate) (4.12.2)\n","Requirement already satisfied: sympy in /usr/local/lib/python3.10/dist-packages (from torch\u003e=1.10.0-\u003eaccelerate) (1.12.1)\n","Requirement already satisfied: networkx in /usr/local/lib/python3.10/dist-packages (from torch\u003e=1.10.0-\u003eaccelerate) (3.3)\n","Requirement already satisfied: jinja2 in /usr/local/lib/python3.10/dist-packages (from torch\u003e=1.10.0-\u003eaccelerate) (3.1.4)\n","Requirement already satisfied: fsspec in /usr/local/lib/python3.10/dist-packages (from torch\u003e=1.10.0-\u003eaccelerate) (2023.6.0)\n","Requirement already satisfied: nvidia-cuda-nvrtc-cu12==12.1.105 in /usr/local/lib/python3.10/dist-packages (from torch\u003e=1.10.0-\u003eaccelerate) (12.1.105)\n","Requirement already satisfied: nvidia-cuda-runtime-cu12==12.1.105 in /usr/local/lib/python3.10/dist-packages (from torch\u003e=1.10.0-\u003eaccelerate) (12.1.105)\n","Requirement already satisfied: nvidia-cuda-cupti-cu12==12.1.105 in /usr/local/lib/python3.10/dist-packages (from torch\u003e=1.10.0-\u003eaccelerate) (12.1.105)\n","Requirement already satisfied: nvidia-cudnn-cu12==8.9.2.26 in /usr/local/lib/python3.10/dist-packages (from torch\u003e=1.10.0-\u003eaccelerate) (8.9.2.26)\n","Requirement already satisfied: nvidia-cublas-cu12==12.1.3.1 in /usr/local/lib/python3.10/dist-packages (from torch\u003e=1.10.0-\u003eaccelerate) (12.1.3.1)\n","Requirement already satisfied: nvidia-cufft-cu12==11.0.2.54 in /usr/local/lib/python3.10/dist-packages (from torch\u003e=1.10.0-\u003eaccelerate) (11.0.2.54)\n","Requirement already satisfied: nvidia-curand-cu12==10.3.2.106 in /usr/local/lib/python3.10/dist-packages (from torch\u003e=1.10.0-\u003eaccelerate) (10.3.2.106)\n","Requirement already satisfied: nvidia-cusolver-cu12==11.4.5.107 in /usr/local/lib/python3.10/dist-packages (from torch\u003e=1.10.0-\u003eaccelerate) (11.4.5.107)\n","Requirement already satisfied: nvidia-cusparse-cu12==12.1.0.106 in /usr/local/lib/python3.10/dist-packages (from torch\u003e=1.10.0-\u003eaccelerate) (12.1.0.106)\n","Requirement already satisfied: nvidia-nccl-cu12==2.20.5 in /usr/local/lib/python3.10/dist-packages (from torch\u003e=1.10.0-\u003eaccelerate) (2.20.5)\n","Requirement already satisfied: nvidia-nvtx-cu12==12.1.105 in /usr/local/lib/python3.10/dist-packages (from torch\u003e=1.10.0-\u003eaccelerate) (12.1.105)\n","Requirement already satisfied: triton==2.3.0 in /usr/local/lib/python3.10/dist-packages (from torch\u003e=1.10.0-\u003eaccelerate) (2.3.0)\n","Requirement already satisfied: nvidia-nvjitlink-cu12 in /usr/local/lib/python3.10/dist-packages (from nvidia-cusolver-cu12==11.4.5.107-\u003etorch\u003e=1.10.0-\u003eaccelerate) (12.5.82)\n","Requirement already satisfied: requests in /usr/local/lib/python3.10/dist-packages (from huggingface-hub-\u003eaccelerate) (2.32.3)\n","Requirement already satisfied: tqdm\u003e=4.42.1 in /usr/local/lib/python3.10/dist-packages (from huggingface-hub-\u003eaccelerate) (4.66.4)\n","Requirement already satisfied: MarkupSafe\u003e=2.0 in /usr/local/lib/python3.10/dist-packages (from jinja2-\u003etorch\u003e=1.10.0-\u003eaccelerate) (2.1.5)\n","Requirement already satisfied: charset-normalizer\u003c4,\u003e=2 in /usr/local/lib/python3.10/dist-packages (from requests-\u003ehuggingface-hub-\u003eaccelerate) (3.3.2)\n","Requirement already satisfied: idna\u003c4,\u003e=2.5 in /usr/local/lib/python3.10/dist-packages (from requests-\u003ehuggingface-hub-\u003eaccelerate) (3.7)\n","Requirement already satisfied: urllib3\u003c3,\u003e=1.21.1 in /usr/local/lib/python3.10/dist-packages (from requests-\u003ehuggingface-hub-\u003eaccelerate) (2.0.7)\n","Requirement already satisfied: certifi\u003e=2017.4.17 in /usr/local/lib/python3.10/dist-packages (from requests-\u003ehuggingface-hub-\u003eaccelerate) (2024.6.2)\n","Requirement already satisfied: mpmath\u003c1.4.0,\u003e=1.1.0 in /usr/local/lib/python3.10/dist-packages (from sympy-\u003etorch\u003e=1.10.0-\u003eaccelerate) (1.3.0)\n"]}],"source":["pip install accelerate"]},{"cell_type":"code","execution_count":4,"metadata":{"colab":{"base_uri":"https://localhost:8080/"},"executionInfo":{"elapsed":6675,"status":"ok","timestamp":1719923965568,"user":{"displayName":"Pilar Raquel Hernández Galayo","userId":"08773972401991624404"},"user_tz":-120},"id":"DjDsEzuAUKOb","outputId":"c15d240f-daac-4cc0-d211-8e46913af897"},"outputs":[{"name":"stdout","output_type":"stream","text":["Requirement already satisfied: evaluate in /usr/local/lib/python3.10/dist-packages (0.4.2)\n","Requirement already satisfied: datasets\u003e=2.0.0 in /usr/local/lib/python3.10/dist-packages (from evaluate) (2.20.0)\n","Requirement already satisfied: numpy\u003e=1.17 in /usr/local/lib/python3.10/dist-packages (from evaluate) (1.25.2)\n","Requirement already satisfied: dill in /usr/local/lib/python3.10/dist-packages (from evaluate) (0.3.8)\n","Requirement already satisfied: pandas in /usr/local/lib/python3.10/dist-packages (from evaluate) (2.0.3)\n","Requirement already satisfied: requests\u003e=2.19.0 in /usr/local/lib/python3.10/dist-packages (from evaluate) (2.32.3)\n","Requirement already satisfied: tqdm\u003e=4.62.1 in /usr/local/lib/python3.10/dist-packages (from evaluate) (4.66.4)\n","Requirement already satisfied: xxhash in /usr/local/lib/python3.10/dist-packages (from evaluate) (3.4.1)\n","Requirement already satisfied: multiprocess in /usr/local/lib/python3.10/dist-packages (from evaluate) (0.70.16)\n","Requirement already satisfied: fsspec[http]\u003e=2021.05.0 in /usr/local/lib/python3.10/dist-packages (from evaluate) (2023.6.0)\n","Requirement already satisfied: huggingface-hub\u003e=0.7.0 in /usr/local/lib/python3.10/dist-packages (from evaluate) (0.23.4)\n","Requirement already satisfied: packaging in /usr/local/lib/python3.10/dist-packages (from evaluate) (24.1)\n","Requirement already satisfied: filelock in /usr/local/lib/python3.10/dist-packages (from datasets\u003e=2.0.0-\u003eevaluate) (3.15.4)\n","Requirement already satisfied: pyarrow\u003e=15.0.0 in /usr/local/lib/python3.10/dist-packages (from datasets\u003e=2.0.0-\u003eevaluate) (16.1.0)\n","Requirement already satisfied: pyarrow-hotfix in /usr/local/lib/python3.10/dist-packages (from datasets\u003e=2.0.0-\u003eevaluate) (0.6)\n","Requirement already satisfied: aiohttp in /usr/local/lib/python3.10/dist-packages (from datasets\u003e=2.0.0-\u003eevaluate) (3.9.5)\n","Requirement already satisfied: pyyaml\u003e=5.1 in /usr/local/lib/python3.10/dist-packages (from datasets\u003e=2.0.0-\u003eevaluate) (6.0.1)\n","Requirement already satisfied: typing-extensions\u003e=3.7.4.3 in /usr/local/lib/python3.10/dist-packages (from huggingface-hub\u003e=0.7.0-\u003eevaluate) (4.12.2)\n","Requirement already satisfied: charset-normalizer\u003c4,\u003e=2 in /usr/local/lib/python3.10/dist-packages (from requests\u003e=2.19.0-\u003eevaluate) (3.3.2)\n","Requirement already satisfied: idna\u003c4,\u003e=2.5 in /usr/local/lib/python3.10/dist-packages (from requests\u003e=2.19.0-\u003eevaluate) (3.7)\n","Requirement already satisfied: urllib3\u003c3,\u003e=1.21.1 in /usr/local/lib/python3.10/dist-packages (from requests\u003e=2.19.0-\u003eevaluate) (2.0.7)\n","Requirement already satisfied: certifi\u003e=2017.4.17 in /usr/local/lib/python3.10/dist-packages (from requests\u003e=2.19.0-\u003eevaluate) (2024.6.2)\n","Requirement already satisfied: python-dateutil\u003e=2.8.2 in /usr/local/lib/python3.10/dist-packages (from pandas-\u003eevaluate) (2.8.2)\n","Requirement already satisfied: pytz\u003e=2020.1 in /usr/local/lib/python3.10/dist-packages (from pandas-\u003eevaluate) (2023.4)\n","Requirement already satisfied: tzdata\u003e=2022.1 in /usr/local/lib/python3.10/dist-packages (from pandas-\u003eevaluate) (2024.1)\n","Requirement already satisfied: aiosignal\u003e=1.1.2 in /usr/local/lib/python3.10/dist-packages (from aiohttp-\u003edatasets\u003e=2.0.0-\u003eevaluate) (1.3.1)\n","Requirement already satisfied: attrs\u003e=17.3.0 in /usr/local/lib/python3.10/dist-packages (from aiohttp-\u003edatasets\u003e=2.0.0-\u003eevaluate) (23.2.0)\n","Requirement already satisfied: frozenlist\u003e=1.1.1 in /usr/local/lib/python3.10/dist-packages (from aiohttp-\u003edatasets\u003e=2.0.0-\u003eevaluate) (1.4.1)\n","Requirement already satisfied: multidict\u003c7.0,\u003e=4.5 in /usr/local/lib/python3.10/dist-packages (from aiohttp-\u003edatasets\u003e=2.0.0-\u003eevaluate) (6.0.5)\n","Requirement already satisfied: yarl\u003c2.0,\u003e=1.0 in /usr/local/lib/python3.10/dist-packages (from aiohttp-\u003edatasets\u003e=2.0.0-\u003eevaluate) (1.9.4)\n","Requirement already satisfied: async-timeout\u003c5.0,\u003e=4.0 in /usr/local/lib/python3.10/dist-packages (from aiohttp-\u003edatasets\u003e=2.0.0-\u003eevaluate) (4.0.3)\n","Requirement already satisfied: six\u003e=1.5 in /usr/local/lib/python3.10/dist-packages (from python-dateutil\u003e=2.8.2-\u003epandas-\u003eevaluate) (1.16.0)\n"]}],"source":["pip install evaluate"]},{"cell_type":"code","execution_count":null,"metadata":{"colab":{"base_uri":"https://localhost:8080/"},"id":"9h5H-7pWUMhe","outputId":"7e94b3ea-ead6-46dd-cfed-2f7788323f6f"},"outputs":[{"name":"stdout","output_type":"stream","text":["Requirement already satisfied: gluonts in /usr/local/lib/python3.10/dist-packages (0.15.1)\n","Requirement already satisfied: numpy~=1.16 in /usr/local/lib/python3.10/dist-packages (from gluonts) (1.25.2)\n","Requirement already satisfied: pandas\u003c3,\u003e=1.0 in /usr/local/lib/python3.10/dist-packages (from gluonts) (2.0.3)\n","Requirement already satisfied: pydantic\u003c3,\u003e=1.7 in /usr/local/lib/python3.10/dist-packages (from gluonts) (2.7.4)\n","Requirement already satisfied: tqdm~=4.23 in /usr/local/lib/python3.10/dist-packages (from gluonts) (4.66.4)\n","Requirement already satisfied: toolz~=0.10 in /usr/local/lib/python3.10/dist-packages (from gluonts) (0.12.1)\n","Requirement already satisfied: typing-extensions~=4.0 in /usr/local/lib/python3.10/dist-packages (from gluonts) (4.12.2)\n","Requirement already satisfied: python-dateutil\u003e=2.8.2 in /usr/local/lib/python3.10/dist-packages (from pandas\u003c3,\u003e=1.0-\u003egluonts) (2.8.2)\n","Requirement already satisfied: pytz\u003e=2020.1 in /usr/local/lib/python3.10/dist-packages (from pandas\u003c3,\u003e=1.0-\u003egluonts) (2023.4)\n","Requirement already satisfied: tzdata\u003e=2022.1 in /usr/local/lib/python3.10/dist-packages (from pandas\u003c3,\u003e=1.0-\u003egluonts) (2024.1)\n","Requirement already satisfied: annotated-types\u003e=0.4.0 in /usr/local/lib/python3.10/dist-packages (from pydantic\u003c3,\u003e=1.7-\u003egluonts) (0.7.0)\n","Requirement already satisfied: pydantic-core==2.18.4 in /usr/local/lib/python3.10/dist-packages (from pydantic\u003c3,\u003e=1.7-\u003egluonts) (2.18.4)\n","Requirement already satisfied: six\u003e=1.5 in /usr/local/lib/python3.10/dist-packages (from python-dateutil\u003e=2.8.2-\u003epandas\u003c3,\u003e=1.0-\u003egluonts) (1.16.0)\n"]}],"source":["pip install gluonts"]},{"cell_type":"code","execution_count":null,"metadata":{"colab":{"background_save":true},"id":"Y4eeRyDmdkfr"},"outputs":[{"name":"stderr","output_type":"stream","text":["ERROR:root:Internal Python error in the inspect module.\n","Below is the traceback from this internal error.\n","\n","ERROR:root:Internal Python error in the inspect module.\n","Below is the traceback from this internal error.\n","\n","ERROR:root:Internal Python error in the inspect module.\n","Below is the traceback from this internal error.\n","\n"]},{"name":"stdout","output_type":"stream","text":["Mounted at /content/drive\n","Traceback (most recent call last):\n","  File \"/usr/local/lib/python3.10/dist-packages/IPython/core/interactiveshell.py\", line 3553, in run_code\n","    exec(code_obj, self.user_global_ns, self.user_ns)\n","  File \"\u003cipython-input-6-e9bcb203ccf9\u003e\", line 3, in \u003ccell line: 3\u003e\n","    get_ipython().run_line_magic('cd', '/content/drive/MyDrive/TFG_Training_T/T12')\n","  File \"/usr/local/lib/python3.10/dist-packages/IPython/core/interactiveshell.py\", line 2418, in run_line_magic\n","    result = fn(*args, **kwargs)\n","  File \"\u003cdecorator-gen-85\u003e\", line 2, in cd\n","  File \"/usr/local/lib/python3.10/dist-packages/IPython/core/magic.py\", line 187, in \u003clambda\u003e\n","    call = lambda f, *a, **k: f(*a, **k)\n","  File \"/usr/local/lib/python3.10/dist-packages/IPython/core/magics/osm.py\", line 342, in cd\n","    oldcwd = os.getcwd()\n","OSError: [Errno 107] Transport endpoint is not connected\n","\n","During handling of the above exception, another exception occurred:\n","\n","Traceback (most recent call last):\n","  File \"/usr/local/lib/python3.10/dist-packages/IPython/core/interactiveshell.py\", line 2099, in showtraceback\n","    stb = value._render_traceback_()\n","AttributeError: 'OSError' object has no attribute '_render_traceback_'\n","\n","During handling of the above exception, another exception occurred:\n","\n","Traceback (most recent call last):\n","  File \"/usr/local/lib/python3.10/dist-packages/IPython/core/ultratb.py\", line 1101, in get_records\n","    return _fixed_getinnerframes(etb, number_of_lines_of_context, tb_offset)\n","  File \"/usr/local/lib/python3.10/dist-packages/IPython/core/ultratb.py\", line 248, in wrapped\n","    return f(*args, **kwargs)\n","  File \"/usr/local/lib/python3.10/dist-packages/IPython/core/ultratb.py\", line 281, in _fixed_getinnerframes\n","    records = fix_frame_records_filenames(inspect.getinnerframes(etb, context))\n","  File \"/usr/lib/python3.10/inspect.py\", line 1662, in getinnerframes\n","    frameinfo = (tb.tb_frame,) + getframeinfo(tb, context)\n","  File \"/usr/lib/python3.10/inspect.py\", line 1620, in getframeinfo\n","    filename = getsourcefile(frame) or getfile(frame)\n","  File \"/usr/lib/python3.10/inspect.py\", line 829, in getsourcefile\n","    module = getmodule(object, filename)\n","  File \"/usr/lib/python3.10/inspect.py\", line 861, in getmodule\n","    file = getabsfile(object, _filename)\n","  File \"/usr/lib/python3.10/inspect.py\", line 845, in getabsfile\n","    return os.path.normcase(os.path.abspath(_filename))\n","  File \"/usr/lib/python3.10/posixpath.py\", line 384, in abspath\n","    cwd = os.getcwd()\n","OSError: [Errno 107] Transport endpoint is not connected\n","Traceback (most recent call last):\n","  File \"/usr/local/lib/python3.10/dist-packages/IPython/core/interactiveshell.py\", line 3553, in run_code\n","    exec(code_obj, self.user_global_ns, self.user_ns)\n","  File \"\u003cipython-input-6-e9bcb203ccf9\u003e\", line 3, in \u003ccell line: 3\u003e\n","    get_ipython().run_line_magic('cd', '/content/drive/MyDrive/TFG_Training_T/T12')\n","  File \"/usr/local/lib/python3.10/dist-packages/IPython/core/interactiveshell.py\", line 2418, in run_line_magic\n","    result = fn(*args, **kwargs)\n","  File \"\u003cdecorator-gen-85\u003e\", line 2, in cd\n","  File \"/usr/local/lib/python3.10/dist-packages/IPython/core/magic.py\", line 187, in \u003clambda\u003e\n","    call = lambda f, *a, **k: f(*a, **k)\n","  File \"/usr/local/lib/python3.10/dist-packages/IPython/core/magics/osm.py\", line 342, in cd\n","    oldcwd = os.getcwd()\n","OSError: [Errno 107] Transport endpoint is not connected\n","\n","During handling of the above exception, another exception occurred:\n","\n","Traceback (most recent call last):\n","  File \"/usr/local/lib/python3.10/dist-packages/IPython/core/interactiveshell.py\", line 2099, in showtraceback\n","    stb = value._render_traceback_()\n","AttributeError: 'OSError' object has no attribute '_render_traceback_'\n","\n","During handling of the above exception, another exception occurred:\n","\n","Traceback (most recent call last):\n","  File \"/usr/local/lib/python3.10/dist-packages/IPython/core/interactiveshell.py\", line 3473, in run_ast_nodes\n","    if (await self.run_code(code, result,  async_=asy)):\n","  File \"/usr/local/lib/python3.10/dist-packages/IPython/core/interactiveshell.py\", line 3575, in run_code\n","    self.showtraceback(running_compiled_code=True)\n","  File \"/usr/local/lib/python3.10/dist-packages/IPython/core/interactiveshell.py\", line 2101, in showtraceback\n","    stb = self.InteractiveTB.structured_traceback(etype,\n","  File \"/usr/local/lib/python3.10/dist-packages/IPython/core/ultratb.py\", line 1367, in structured_traceback\n","    return FormattedTB.structured_traceback(\n","  File \"/usr/local/lib/python3.10/dist-packages/IPython/core/ultratb.py\", line 1267, in structured_traceback\n","    return VerboseTB.structured_traceback(\n","  File \"/usr/local/lib/python3.10/dist-packages/IPython/core/ultratb.py\", line 1124, in structured_traceback\n","    formatted_exception = self.format_exception_as_a_whole(etype, evalue, etb, number_of_lines_of_context,\n","  File \"/usr/local/lib/python3.10/dist-packages/IPython/core/ultratb.py\", line 1082, in format_exception_as_a_whole\n","    last_unique, recursion_repeat = find_recursion(orig_etype, evalue, records)\n","  File \"/usr/local/lib/python3.10/dist-packages/IPython/core/ultratb.py\", line 382, in find_recursion\n","    return len(records), 0\n","TypeError: object of type 'NoneType' has no len()\n","\n","During handling of the above exception, another exception occurred:\n","\n","Traceback (most recent call last):\n","  File \"/usr/local/lib/python3.10/dist-packages/IPython/core/interactiveshell.py\", line 2099, in showtraceback\n","    stb = value._render_traceback_()\n","AttributeError: 'TypeError' object has no attribute '_render_traceback_'\n","\n","During handling of the above exception, another exception occurred:\n","\n","Traceback (most recent call last):\n","  File \"/usr/local/lib/python3.10/dist-packages/IPython/core/ultratb.py\", line 1101, in get_records\n","    return _fixed_getinnerframes(etb, number_of_lines_of_context, tb_offset)\n","  File \"/usr/local/lib/python3.10/dist-packages/IPython/core/ultratb.py\", line 248, in wrapped\n","    return f(*args, **kwargs)\n","  File \"/usr/local/lib/python3.10/dist-packages/IPython/core/ultratb.py\", line 281, in _fixed_getinnerframes\n","    records = fix_frame_records_filenames(inspect.getinnerframes(etb, context))\n","  File \"/usr/lib/python3.10/inspect.py\", line 1662, in getinnerframes\n","    frameinfo = (tb.tb_frame,) + getframeinfo(tb, context)\n","  File \"/usr/lib/python3.10/inspect.py\", line 1620, in getframeinfo\n","    filename = getsourcefile(frame) or getfile(frame)\n","  File \"/usr/lib/python3.10/inspect.py\", line 829, in getsourcefile\n","    module = getmodule(object, filename)\n","  File \"/usr/lib/python3.10/inspect.py\", line 861, in getmodule\n","    file = getabsfile(object, _filename)\n","  File \"/usr/lib/python3.10/inspect.py\", line 845, in getabsfile\n","    return os.path.normcase(os.path.abspath(_filename))\n","  File \"/usr/lib/python3.10/posixpath.py\", line 384, in abspath\n","    cwd = os.getcwd()\n","OSError: [Errno 107] Transport endpoint is not connected\n","Traceback (most recent call last):\n","  File \"/usr/local/lib/python3.10/dist-packages/IPython/core/interactiveshell.py\", line 3553, in run_code\n","    exec(code_obj, self.user_global_ns, self.user_ns)\n","  File \"\u003cipython-input-6-e9bcb203ccf9\u003e\", line 3, in \u003ccell line: 3\u003e\n","    get_ipython().run_line_magic('cd', '/content/drive/MyDrive/TFG_Training_T/T12')\n","  File \"/usr/local/lib/python3.10/dist-packages/IPython/core/interactiveshell.py\", line 2418, in run_line_magic\n","    result = fn(*args, **kwargs)\n","  File \"\u003cdecorator-gen-85\u003e\", line 2, in cd\n","  File \"/usr/local/lib/python3.10/dist-packages/IPython/core/magic.py\", line 187, in \u003clambda\u003e\n","    call = lambda f, *a, **k: f(*a, **k)\n","  File \"/usr/local/lib/python3.10/dist-packages/IPython/core/magics/osm.py\", line 342, in cd\n","    oldcwd = os.getcwd()\n","OSError: [Errno 107] Transport endpoint is not connected\n","\n","During handling of the above exception, another exception occurred:\n","\n","Traceback (most recent call last):\n","  File \"/usr/local/lib/python3.10/dist-packages/IPython/core/interactiveshell.py\", line 2099, in showtraceback\n","    stb = value._render_traceback_()\n","AttributeError: 'OSError' object has no attribute '_render_traceback_'\n","\n","During handling of the above exception, another exception occurred:\n","\n","Traceback (most recent call last):\n","  File \"/usr/local/lib/python3.10/dist-packages/IPython/core/interactiveshell.py\", line 3473, in run_ast_nodes\n","    if (await self.run_code(code, result,  async_=asy)):\n","  File \"/usr/local/lib/python3.10/dist-packages/IPython/core/interactiveshell.py\", line 3575, in run_code\n","    self.showtraceback(running_compiled_code=True)\n","  File \"/usr/local/lib/python3.10/dist-packages/IPython/core/interactiveshell.py\", line 2101, in showtraceback\n","    stb = self.InteractiveTB.structured_traceback(etype,\n","  File \"/usr/local/lib/python3.10/dist-packages/IPython/core/ultratb.py\", line 1367, in structured_traceback\n","    return FormattedTB.structured_traceback(\n","  File \"/usr/local/lib/python3.10/dist-packages/IPython/core/ultratb.py\", line 1267, in structured_traceback\n","    return VerboseTB.structured_traceback(\n","  File \"/usr/local/lib/python3.10/dist-packages/IPython/core/ultratb.py\", line 1124, in structured_traceback\n","    formatted_exception = self.format_exception_as_a_whole(etype, evalue, etb, number_of_lines_of_context,\n","  File \"/usr/local/lib/python3.10/dist-packages/IPython/core/ultratb.py\", line 1082, in format_exception_as_a_whole\n","    last_unique, recursion_repeat = find_recursion(orig_etype, evalue, records)\n","  File \"/usr/local/lib/python3.10/dist-packages/IPython/core/ultratb.py\", line 382, in find_recursion\n","    return len(records), 0\n","TypeError: object of type 'NoneType' has no len()\n","\n","During handling of the above exception, another exception occurred:\n","\n","Traceback (most recent call last):\n","  File \"/usr/local/lib/python3.10/dist-packages/IPython/core/interactiveshell.py\", line 2099, in showtraceback\n","    stb = value._render_traceback_()\n","AttributeError: 'TypeError' object has no attribute '_render_traceback_'\n","\n","During handling of the above exception, another exception occurred:\n","\n","Traceback (most recent call last):\n","  File \"/usr/local/lib/python3.10/dist-packages/IPython/core/interactiveshell.py\", line 3030, in _run_cell\n","    return runner(coro)\n","  File \"/usr/local/lib/python3.10/dist-packages/IPython/core/async_helpers.py\", line 78, in _pseudo_sync_runner\n","    coro.send(None)\n","  File \"/usr/local/lib/python3.10/dist-packages/IPython/core/interactiveshell.py\", line 3257, in run_cell_async\n","    has_raised = await self.run_ast_nodes(code_ast.body, cell_name,\n","  File \"/usr/local/lib/python3.10/dist-packages/IPython/core/interactiveshell.py\", line 3492, in run_ast_nodes\n","    self.showtraceback()\n","  File \"/usr/local/lib/python3.10/dist-packages/IPython/core/interactiveshell.py\", line 2101, in showtraceback\n","    stb = self.InteractiveTB.structured_traceback(etype,\n","  File \"/usr/local/lib/python3.10/dist-packages/IPython/core/ultratb.py\", line 1367, in structured_traceback\n","    return FormattedTB.structured_traceback(\n","  File \"/usr/local/lib/python3.10/dist-packages/IPython/core/ultratb.py\", line 1267, in structured_traceback\n","    return VerboseTB.structured_traceback(\n","  File \"/usr/local/lib/python3.10/dist-packages/IPython/core/ultratb.py\", line 1142, in structured_traceback\n","    formatted_exceptions += self.format_exception_as_a_whole(etype, evalue, etb, lines_of_context,\n","  File \"/usr/local/lib/python3.10/dist-packages/IPython/core/ultratb.py\", line 1082, in format_exception_as_a_whole\n","    last_unique, recursion_repeat = find_recursion(orig_etype, evalue, records)\n","  File \"/usr/local/lib/python3.10/dist-packages/IPython/core/ultratb.py\", line 382, in find_recursion\n","    return len(records), 0\n","TypeError: object of type 'NoneType' has no len()\n","\n","During handling of the above exception, another exception occurred:\n","\n","Traceback (most recent call last):\n","  File \"/usr/local/lib/python3.10/dist-packages/IPython/core/interactiveshell.py\", line 2099, in showtraceback\n","    stb = value._render_traceback_()\n","AttributeError: 'TypeError' object has no attribute '_render_traceback_'\n","\n","During handling of the above exception, another exception occurred:\n","\n","Traceback (most recent call last):\n","  File \"/usr/local/lib/python3.10/dist-packages/IPython/core/ultratb.py\", line 1101, in get_records\n","    return _fixed_getinnerframes(etb, number_of_lines_of_context, tb_offset)\n","  File \"/usr/local/lib/python3.10/dist-packages/IPython/core/ultratb.py\", line 248, in wrapped\n","    return f(*args, **kwargs)\n","  File \"/usr/local/lib/python3.10/dist-packages/IPython/core/ultratb.py\", line 281, in _fixed_getinnerframes\n","    records = fix_frame_records_filenames(inspect.getinnerframes(etb, context))\n","  File \"/usr/lib/python3.10/inspect.py\", line 1662, in getinnerframes\n","    frameinfo = (tb.tb_frame,) + getframeinfo(tb, context)\n","  File \"/usr/lib/python3.10/inspect.py\", line 1620, in getframeinfo\n","    filename = getsourcefile(frame) or getfile(frame)\n","  File \"/usr/lib/python3.10/inspect.py\", line 829, in getsourcefile\n","    module = getmodule(object, filename)\n","  File \"/usr/lib/python3.10/inspect.py\", line 861, in getmodule\n","    file = getabsfile(object, _filename)\n","  File \"/usr/lib/python3.10/inspect.py\", line 845, in getabsfile\n","    return os.path.normcase(os.path.abspath(_filename))\n","  File \"/usr/lib/python3.10/posixpath.py\", line 384, in abspath\n","    cwd = os.getcwd()\n","OSError: [Errno 107] Transport endpoint is not connected\n"]}],"source":["from google.colab import drive\n","drive.mount(\"/content/drive\", force_remount=True)\n","%cd /content/drive/MyDrive/TFG_Training_T/T12\n","!python main.py"]}],"metadata":{"accelerator":"GPU","colab":{"gpuType":"T4","name":"","version":""},"kernelspec":{"display_name":"Python 3","name":"python3"},"language_info":{"name":"python"}},"nbformat":4,"nbformat_minor":0}