{"cells":[{"cell_type":"code","execution_count":2,"metadata":{"colab":{"base_uri":"https://localhost:8080/"},"executionInfo":{"elapsed":12631,"status":"ok","timestamp":1719936219853,"user":{"displayName":"Antonio Luis González Hernández","userId":"00245708288176373104"},"user_tz":-120},"id":"SuKs3ewFvO2p","outputId":"30f0ba34-5445-451c-d86b-2d342a5c7c4b"},"outputs":[{"name":"stdout","output_type":"stream","text":["Collecting datasets\n","  Downloading datasets-2.20.0-py3-none-any.whl (547 kB)\n","\u001b[2K     \u001b[90m━━━━━━━━━━━━━━━━━━━━━━━━━━━━━━━━━━━━━━━━\u001b[0m \u001b[32m547.8/547.8 kB\u001b[0m \u001b[31m7.9 MB/s\u001b[0m eta \u001b[36m0:00:00\u001b[0m\n","\u001b[?25hRequirement already satisfied: filelock in /usr/local/lib/python3.10/dist-packages (from datasets) (3.15.4)\n","Requirement already satisfied: numpy\u003e=1.17 in /usr/local/lib/python3.10/dist-packages (from datasets) (1.25.2)\n","Collecting pyarrow\u003e=15.0.0 (from datasets)\n","  Downloading pyarrow-16.1.0-cp310-cp310-manylinux_2_28_x86_64.whl (40.8 MB)\n","\u001b[2K     \u001b[90m━━━━━━━━━━━━━━━━━━━━━━━━━━━━━━━━━━━━━━━━\u001b[0m \u001b[32m40.8/40.8 MB\u001b[0m \u001b[31m22.8 MB/s\u001b[0m eta \u001b[36m0:00:00\u001b[0m\n","\u001b[?25hRequirement already satisfied: pyarrow-hotfix in /usr/local/lib/python3.10/dist-packages (from datasets) (0.6)\n","Collecting dill\u003c0.3.9,\u003e=0.3.0 (from datasets)\n","  Downloading dill-0.3.8-py3-none-any.whl (116 kB)\n","\u001b[2K     \u001b[90m━━━━━━━━━━━━━━━━━━━━━━━━━━━━━━━━━━━━━━━━\u001b[0m \u001b[32m116.3/116.3 kB\u001b[0m \u001b[31m15.6 MB/s\u001b[0m eta \u001b[36m0:00:00\u001b[0m\n","\u001b[?25hRequirement already satisfied: pandas in /usr/local/lib/python3.10/dist-packages (from datasets) (2.0.3)\n","Collecting requests\u003e=2.32.2 (from datasets)\n","  Downloading requests-2.32.3-py3-none-any.whl (64 kB)\n","\u001b[2K     \u001b[90m━━━━━━━━━━━━━━━━━━━━━━━━━━━━━━━━━━━━━━━━\u001b[0m \u001b[32m64.9/64.9 kB\u001b[0m \u001b[31m8.6 MB/s\u001b[0m eta \u001b[36m0:00:00\u001b[0m\n","\u001b[?25hRequirement already satisfied: tqdm\u003e=4.66.3 in /usr/local/lib/python3.10/dist-packages (from datasets) (4.66.4)\n","Collecting xxhash (from datasets)\n","  Downloading xxhash-3.4.1-cp310-cp310-manylinux_2_17_x86_64.manylinux2014_x86_64.whl (194 kB)\n","\u001b[2K     \u001b[90m━━━━━━━━━━━━━━━━━━━━━━━━━━━━━━━━━━━━━━━━\u001b[0m \u001b[32m194.1/194.1 kB\u001b[0m \u001b[31m16.8 MB/s\u001b[0m eta \u001b[36m0:00:00\u001b[0m\n","\u001b[?25hCollecting multiprocess (from datasets)\n","  Downloading multiprocess-0.70.16-py310-none-any.whl (134 kB)\n","\u001b[2K     \u001b[90m━━━━━━━━━━━━━━━━━━━━━━━━━━━━━━━━━━━━━━━━\u001b[0m \u001b[32m134.8/134.8 kB\u001b[0m \u001b[31m17.6 MB/s\u001b[0m eta \u001b[36m0:00:00\u001b[0m\n","\u001b[?25hRequirement already satisfied: fsspec[http]\u003c=2024.5.0,\u003e=2023.1.0 in /usr/local/lib/python3.10/dist-packages (from datasets) (2023.6.0)\n","Requirement already satisfied: aiohttp in /usr/local/lib/python3.10/dist-packages (from datasets) (3.9.5)\n","Requirement already satisfied: huggingface-hub\u003e=0.21.2 in /usr/local/lib/python3.10/dist-packages (from datasets) (0.23.4)\n","Requirement already satisfied: packaging in /usr/local/lib/python3.10/dist-packages (from datasets) (24.1)\n","Requirement already satisfied: pyyaml\u003e=5.1 in /usr/local/lib/python3.10/dist-packages (from datasets) (6.0.1)\n","Requirement already satisfied: aiosignal\u003e=1.1.2 in /usr/local/lib/python3.10/dist-packages (from aiohttp-\u003edatasets) (1.3.1)\n","Requirement already satisfied: attrs\u003e=17.3.0 in /usr/local/lib/python3.10/dist-packages (from aiohttp-\u003edatasets) (23.2.0)\n","Requirement already satisfied: frozenlist\u003e=1.1.1 in /usr/local/lib/python3.10/dist-packages (from aiohttp-\u003edatasets) (1.4.1)\n","Requirement already satisfied: multidict\u003c7.0,\u003e=4.5 in /usr/local/lib/python3.10/dist-packages (from aiohttp-\u003edatasets) (6.0.5)\n","Requirement already satisfied: yarl\u003c2.0,\u003e=1.0 in /usr/local/lib/python3.10/dist-packages (from aiohttp-\u003edatasets) (1.9.4)\n","Requirement already satisfied: async-timeout\u003c5.0,\u003e=4.0 in /usr/local/lib/python3.10/dist-packages (from aiohttp-\u003edatasets) (4.0.3)\n","Requirement already satisfied: typing-extensions\u003e=3.7.4.3 in /usr/local/lib/python3.10/dist-packages (from huggingface-hub\u003e=0.21.2-\u003edatasets) (4.12.2)\n","Requirement already satisfied: charset-normalizer\u003c4,\u003e=2 in /usr/local/lib/python3.10/dist-packages (from requests\u003e=2.32.2-\u003edatasets) (3.3.2)\n","Requirement already satisfied: idna\u003c4,\u003e=2.5 in /usr/local/lib/python3.10/dist-packages (from requests\u003e=2.32.2-\u003edatasets) (3.7)\n","Requirement already satisfied: urllib3\u003c3,\u003e=1.21.1 in /usr/local/lib/python3.10/dist-packages (from requests\u003e=2.32.2-\u003edatasets) (2.0.7)\n","Requirement already satisfied: certifi\u003e=2017.4.17 in /usr/local/lib/python3.10/dist-packages (from requests\u003e=2.32.2-\u003edatasets) (2024.6.2)\n","Requirement already satisfied: python-dateutil\u003e=2.8.2 in /usr/local/lib/python3.10/dist-packages (from pandas-\u003edatasets) (2.8.2)\n","Requirement already satisfied: pytz\u003e=2020.1 in /usr/local/lib/python3.10/dist-packages (from pandas-\u003edatasets) (2023.4)\n","Requirement already satisfied: tzdata\u003e=2022.1 in /usr/local/lib/python3.10/dist-packages (from pandas-\u003edatasets) (2024.1)\n","Requirement already satisfied: six\u003e=1.5 in /usr/local/lib/python3.10/dist-packages (from python-dateutil\u003e=2.8.2-\u003epandas-\u003edatasets) (1.16.0)\n","Installing collected packages: xxhash, requests, pyarrow, dill, multiprocess, datasets\n","  Attempting uninstall: requests\n","    Found existing installation: requests 2.31.0\n","    Uninstalling requests-2.31.0:\n","      Successfully uninstalled requests-2.31.0\n","  Attempting uninstall: pyarrow\n","    Found existing installation: pyarrow 14.0.2\n","    Uninstalling pyarrow-14.0.2:\n","      Successfully uninstalled pyarrow-14.0.2\n","\u001b[31mERROR: pip's dependency resolver does not currently take into account all the packages that are installed. This behaviour is the source of the following dependency conflicts.\n","cudf-cu12 24.4.1 requires pyarrow\u003c15.0.0a0,\u003e=14.0.1, but you have pyarrow 16.1.0 which is incompatible.\n","google-colab 1.0.0 requires requests==2.31.0, but you have requests 2.32.3 which is incompatible.\n","ibis-framework 8.0.0 requires pyarrow\u003c16,\u003e=2, but you have pyarrow 16.1.0 which is incompatible.\u001b[0m\u001b[31m\n","\u001b[0mSuccessfully installed datasets-2.20.0 dill-0.3.8 multiprocess-0.70.16 pyarrow-16.1.0 requests-2.32.3 xxhash-3.4.1\n"]}],"source":["pip install datasets"]},{"cell_type":"code","execution_count":3,"metadata":{"colab":{"base_uri":"https://localhost:8080/"},"executionInfo":{"elapsed":70443,"status":"ok","timestamp":1719936290294,"user":{"displayName":"Antonio Luis González Hernández","userId":"00245708288176373104"},"user_tz":-120},"id":"x53r72kYUIac","outputId":"0adc02e4-b6e7-4566-9a76-25f4acc254ad"},"outputs":[{"name":"stdout","output_type":"stream","text":["Collecting accelerate\n","  Downloading accelerate-0.31.0-py3-none-any.whl (309 kB)\n","\u001b[?25l     \u001b[90m━━━━━━━━━━━━━━━━━━━━━━━━━━━━━━━━━━━━━━━━\u001b[0m \u001b[32m0.0/309.4 kB\u001b[0m \u001b[31m?\u001b[0m eta \u001b[36m-:--:--\u001b[0m\r\u001b[2K     \u001b[91m━━━━━━━━━━━━━━━━━━━━━━\u001b[0m\u001b[91m╸\u001b[0m\u001b[90m━━━━━━━━━━━━━━━━━\u001b[0m \u001b[32m174.1/309.4 kB\u001b[0m \u001b[31m5.2 MB/s\u001b[0m eta \u001b[36m0:00:01\u001b[0m\r\u001b[2K     \u001b[90m━━━━━━━━━━━━━━━━━━━━━━━━━━━━━━━━━━━━━━━━\u001b[0m \u001b[32m309.4/309.4 kB\u001b[0m \u001b[31m5.8 MB/s\u001b[0m eta \u001b[36m0:00:00\u001b[0m\n","\u001b[?25hRequirement already satisfied: numpy\u003e=1.17 in /usr/local/lib/python3.10/dist-packages (from accelerate) (1.25.2)\n","Requirement already satisfied: packaging\u003e=20.0 in /usr/local/lib/python3.10/dist-packages (from accelerate) (24.1)\n","Requirement already satisfied: psutil in /usr/local/lib/python3.10/dist-packages (from accelerate) (5.9.5)\n","Requirement already satisfied: pyyaml in /usr/local/lib/python3.10/dist-packages (from accelerate) (6.0.1)\n","Requirement already satisfied: torch\u003e=1.10.0 in /usr/local/lib/python3.10/dist-packages (from accelerate) (2.3.0+cu121)\n","Requirement already satisfied: huggingface-hub in /usr/local/lib/python3.10/dist-packages (from accelerate) (0.23.4)\n","Requirement already satisfied: safetensors\u003e=0.3.1 in /usr/local/lib/python3.10/dist-packages (from accelerate) (0.4.3)\n","Requirement already satisfied: filelock in /usr/local/lib/python3.10/dist-packages (from torch\u003e=1.10.0-\u003eaccelerate) (3.15.4)\n","Requirement already satisfied: typing-extensions\u003e=4.8.0 in /usr/local/lib/python3.10/dist-packages (from torch\u003e=1.10.0-\u003eaccelerate) (4.12.2)\n","Requirement already satisfied: sympy in /usr/local/lib/python3.10/dist-packages (from torch\u003e=1.10.0-\u003eaccelerate) (1.12.1)\n","Requirement already satisfied: networkx in /usr/local/lib/python3.10/dist-packages (from torch\u003e=1.10.0-\u003eaccelerate) (3.3)\n","Requirement already satisfied: jinja2 in /usr/local/lib/python3.10/dist-packages (from torch\u003e=1.10.0-\u003eaccelerate) (3.1.4)\n","Requirement already satisfied: fsspec in /usr/local/lib/python3.10/dist-packages (from torch\u003e=1.10.0-\u003eaccelerate) (2023.6.0)\n","Collecting nvidia-cuda-nvrtc-cu12==12.1.105 (from torch\u003e=1.10.0-\u003eaccelerate)\n","  Using cached nvidia_cuda_nvrtc_cu12-12.1.105-py3-none-manylinux1_x86_64.whl (23.7 MB)\n","Collecting nvidia-cuda-runtime-cu12==12.1.105 (from torch\u003e=1.10.0-\u003eaccelerate)\n","  Using cached nvidia_cuda_runtime_cu12-12.1.105-py3-none-manylinux1_x86_64.whl (823 kB)\n","Collecting nvidia-cuda-cupti-cu12==12.1.105 (from torch\u003e=1.10.0-\u003eaccelerate)\n","  Using cached nvidia_cuda_cupti_cu12-12.1.105-py3-none-manylinux1_x86_64.whl (14.1 MB)\n","Collecting nvidia-cudnn-cu12==8.9.2.26 (from torch\u003e=1.10.0-\u003eaccelerate)\n","  Using cached nvidia_cudnn_cu12-8.9.2.26-py3-none-manylinux1_x86_64.whl (731.7 MB)\n","Collecting nvidia-cublas-cu12==12.1.3.1 (from torch\u003e=1.10.0-\u003eaccelerate)\n","  Using cached nvidia_cublas_cu12-12.1.3.1-py3-none-manylinux1_x86_64.whl (410.6 MB)\n","Collecting nvidia-cufft-cu12==11.0.2.54 (from torch\u003e=1.10.0-\u003eaccelerate)\n","  Using cached nvidia_cufft_cu12-11.0.2.54-py3-none-manylinux1_x86_64.whl (121.6 MB)\n","Collecting nvidia-curand-cu12==10.3.2.106 (from torch\u003e=1.10.0-\u003eaccelerate)\n","  Using cached nvidia_curand_cu12-10.3.2.106-py3-none-manylinux1_x86_64.whl (56.5 MB)\n","Collecting nvidia-cusolver-cu12==11.4.5.107 (from torch\u003e=1.10.0-\u003eaccelerate)\n","  Using cached nvidia_cusolver_cu12-11.4.5.107-py3-none-manylinux1_x86_64.whl (124.2 MB)\n","Collecting nvidia-cusparse-cu12==12.1.0.106 (from torch\u003e=1.10.0-\u003eaccelerate)\n","  Using cached nvidia_cusparse_cu12-12.1.0.106-py3-none-manylinux1_x86_64.whl (196.0 MB)\n","Collecting nvidia-nccl-cu12==2.20.5 (from torch\u003e=1.10.0-\u003eaccelerate)\n","  Using cached nvidia_nccl_cu12-2.20.5-py3-none-manylinux2014_x86_64.whl (176.2 MB)\n","Collecting nvidia-nvtx-cu12==12.1.105 (from torch\u003e=1.10.0-\u003eaccelerate)\n","  Using cached nvidia_nvtx_cu12-12.1.105-py3-none-manylinux1_x86_64.whl (99 kB)\n","Requirement already satisfied: triton==2.3.0 in /usr/local/lib/python3.10/dist-packages (from torch\u003e=1.10.0-\u003eaccelerate) (2.3.0)\n","Collecting nvidia-nvjitlink-cu12 (from nvidia-cusolver-cu12==11.4.5.107-\u003etorch\u003e=1.10.0-\u003eaccelerate)\n","  Downloading nvidia_nvjitlink_cu12-12.5.82-py3-none-manylinux2014_x86_64.whl (21.3 MB)\n","\u001b[2K     \u001b[90m━━━━━━━━━━━━━━━━━━━━━━━━━━━━━━━━━━━━━━━━\u001b[0m \u001b[32m21.3/21.3 MB\u001b[0m \u001b[31m45.1 MB/s\u001b[0m eta \u001b[36m0:00:00\u001b[0m\n","\u001b[?25hRequirement already satisfied: requests in /usr/local/lib/python3.10/dist-packages (from huggingface-hub-\u003eaccelerate) (2.32.3)\n","Requirement already satisfied: tqdm\u003e=4.42.1 in /usr/local/lib/python3.10/dist-packages (from huggingface-hub-\u003eaccelerate) (4.66.4)\n","Requirement already satisfied: MarkupSafe\u003e=2.0 in /usr/local/lib/python3.10/dist-packages (from jinja2-\u003etorch\u003e=1.10.0-\u003eaccelerate) (2.1.5)\n","Requirement already satisfied: charset-normalizer\u003c4,\u003e=2 in /usr/local/lib/python3.10/dist-packages (from requests-\u003ehuggingface-hub-\u003eaccelerate) (3.3.2)\n","Requirement already satisfied: idna\u003c4,\u003e=2.5 in /usr/local/lib/python3.10/dist-packages (from requests-\u003ehuggingface-hub-\u003eaccelerate) (3.7)\n","Requirement already satisfied: urllib3\u003c3,\u003e=1.21.1 in /usr/local/lib/python3.10/dist-packages (from requests-\u003ehuggingface-hub-\u003eaccelerate) (2.0.7)\n","Requirement already satisfied: certifi\u003e=2017.4.17 in /usr/local/lib/python3.10/dist-packages (from requests-\u003ehuggingface-hub-\u003eaccelerate) (2024.6.2)\n","Requirement already satisfied: mpmath\u003c1.4.0,\u003e=1.1.0 in /usr/local/lib/python3.10/dist-packages (from sympy-\u003etorch\u003e=1.10.0-\u003eaccelerate) (1.3.0)\n","Installing collected packages: nvidia-nvtx-cu12, nvidia-nvjitlink-cu12, nvidia-nccl-cu12, nvidia-curand-cu12, nvidia-cufft-cu12, nvidia-cuda-runtime-cu12, nvidia-cuda-nvrtc-cu12, nvidia-cuda-cupti-cu12, nvidia-cublas-cu12, nvidia-cusparse-cu12, nvidia-cudnn-cu12, nvidia-cusolver-cu12, accelerate\n","Successfully installed accelerate-0.31.0 nvidia-cublas-cu12-12.1.3.1 nvidia-cuda-cupti-cu12-12.1.105 nvidia-cuda-nvrtc-cu12-12.1.105 nvidia-cuda-runtime-cu12-12.1.105 nvidia-cudnn-cu12-8.9.2.26 nvidia-cufft-cu12-11.0.2.54 nvidia-curand-cu12-10.3.2.106 nvidia-cusolver-cu12-11.4.5.107 nvidia-cusparse-cu12-12.1.0.106 nvidia-nccl-cu12-2.20.5 nvidia-nvjitlink-cu12-12.5.82 nvidia-nvtx-cu12-12.1.105\n"]}],"source":["pip install accelerate"]},{"cell_type":"code","execution_count":4,"metadata":{"colab":{"base_uri":"https://localhost:8080/"},"executionInfo":{"elapsed":8259,"status":"ok","timestamp":1719936298549,"user":{"displayName":"Antonio Luis González Hernández","userId":"00245708288176373104"},"user_tz":-120},"id":"DjDsEzuAUKOb","outputId":"4b45c0bc-dcca-4c6f-a4bd-21fac58c7896"},"outputs":[{"name":"stdout","output_type":"stream","text":["Collecting evaluate\n","  Downloading evaluate-0.4.2-py3-none-any.whl (84 kB)\n","\u001b[2K     \u001b[90m━━━━━━━━━━━━━━━━━━━━━━━━━━━━━━━━━━━━━━━━\u001b[0m \u001b[32m84.1/84.1 kB\u001b[0m \u001b[31m2.6 MB/s\u001b[0m eta \u001b[36m0:00:00\u001b[0m\n","\u001b[?25hRequirement already satisfied: datasets\u003e=2.0.0 in /usr/local/lib/python3.10/dist-packages (from evaluate) (2.20.0)\n","Requirement already satisfied: numpy\u003e=1.17 in /usr/local/lib/python3.10/dist-packages (from evaluate) (1.25.2)\n","Requirement already satisfied: dill in /usr/local/lib/python3.10/dist-packages (from evaluate) (0.3.8)\n","Requirement already satisfied: pandas in /usr/local/lib/python3.10/dist-packages (from evaluate) (2.0.3)\n","Requirement already satisfied: requests\u003e=2.19.0 in /usr/local/lib/python3.10/dist-packages (from evaluate) (2.32.3)\n","Requirement already satisfied: tqdm\u003e=4.62.1 in /usr/local/lib/python3.10/dist-packages (from evaluate) (4.66.4)\n","Requirement already satisfied: xxhash in /usr/local/lib/python3.10/dist-packages (from evaluate) (3.4.1)\n","Requirement already satisfied: multiprocess in /usr/local/lib/python3.10/dist-packages (from evaluate) (0.70.16)\n","Requirement already satisfied: fsspec[http]\u003e=2021.05.0 in /usr/local/lib/python3.10/dist-packages (from evaluate) (2023.6.0)\n","Requirement already satisfied: huggingface-hub\u003e=0.7.0 in /usr/local/lib/python3.10/dist-packages (from evaluate) (0.23.4)\n","Requirement already satisfied: packaging in /usr/local/lib/python3.10/dist-packages (from evaluate) (24.1)\n","Requirement already satisfied: filelock in /usr/local/lib/python3.10/dist-packages (from datasets\u003e=2.0.0-\u003eevaluate) (3.15.4)\n","Requirement already satisfied: pyarrow\u003e=15.0.0 in /usr/local/lib/python3.10/dist-packages (from datasets\u003e=2.0.0-\u003eevaluate) (16.1.0)\n","Requirement already satisfied: pyarrow-hotfix in /usr/local/lib/python3.10/dist-packages (from datasets\u003e=2.0.0-\u003eevaluate) (0.6)\n","Requirement already satisfied: aiohttp in /usr/local/lib/python3.10/dist-packages (from datasets\u003e=2.0.0-\u003eevaluate) (3.9.5)\n","Requirement already satisfied: pyyaml\u003e=5.1 in /usr/local/lib/python3.10/dist-packages (from datasets\u003e=2.0.0-\u003eevaluate) (6.0.1)\n","Requirement already satisfied: typing-extensions\u003e=3.7.4.3 in /usr/local/lib/python3.10/dist-packages (from huggingface-hub\u003e=0.7.0-\u003eevaluate) (4.12.2)\n","Requirement already satisfied: charset-normalizer\u003c4,\u003e=2 in /usr/local/lib/python3.10/dist-packages (from requests\u003e=2.19.0-\u003eevaluate) (3.3.2)\n","Requirement already satisfied: idna\u003c4,\u003e=2.5 in /usr/local/lib/python3.10/dist-packages (from requests\u003e=2.19.0-\u003eevaluate) (3.7)\n","Requirement already satisfied: urllib3\u003c3,\u003e=1.21.1 in /usr/local/lib/python3.10/dist-packages (from requests\u003e=2.19.0-\u003eevaluate) (2.0.7)\n","Requirement already satisfied: certifi\u003e=2017.4.17 in /usr/local/lib/python3.10/dist-packages (from requests\u003e=2.19.0-\u003eevaluate) (2024.6.2)\n","Requirement already satisfied: python-dateutil\u003e=2.8.2 in /usr/local/lib/python3.10/dist-packages (from pandas-\u003eevaluate) (2.8.2)\n","Requirement already satisfied: pytz\u003e=2020.1 in /usr/local/lib/python3.10/dist-packages (from pandas-\u003eevaluate) (2023.4)\n","Requirement already satisfied: tzdata\u003e=2022.1 in /usr/local/lib/python3.10/dist-packages (from pandas-\u003eevaluate) (2024.1)\n","Requirement already satisfied: aiosignal\u003e=1.1.2 in /usr/local/lib/python3.10/dist-packages (from aiohttp-\u003edatasets\u003e=2.0.0-\u003eevaluate) (1.3.1)\n","Requirement already satisfied: attrs\u003e=17.3.0 in /usr/local/lib/python3.10/dist-packages (from aiohttp-\u003edatasets\u003e=2.0.0-\u003eevaluate) (23.2.0)\n","Requirement already satisfied: frozenlist\u003e=1.1.1 in /usr/local/lib/python3.10/dist-packages (from aiohttp-\u003edatasets\u003e=2.0.0-\u003eevaluate) (1.4.1)\n","Requirement already satisfied: multidict\u003c7.0,\u003e=4.5 in /usr/local/lib/python3.10/dist-packages (from aiohttp-\u003edatasets\u003e=2.0.0-\u003eevaluate) (6.0.5)\n","Requirement already satisfied: yarl\u003c2.0,\u003e=1.0 in /usr/local/lib/python3.10/dist-packages (from aiohttp-\u003edatasets\u003e=2.0.0-\u003eevaluate) (1.9.4)\n","Requirement already satisfied: async-timeout\u003c5.0,\u003e=4.0 in /usr/local/lib/python3.10/dist-packages (from aiohttp-\u003edatasets\u003e=2.0.0-\u003eevaluate) (4.0.3)\n","Requirement already satisfied: six\u003e=1.5 in /usr/local/lib/python3.10/dist-packages (from python-dateutil\u003e=2.8.2-\u003epandas-\u003eevaluate) (1.16.0)\n","Installing collected packages: evaluate\n","Successfully installed evaluate-0.4.2\n"]}],"source":["pip install evaluate"]},{"cell_type":"code","execution_count":null,"metadata":{"colab":{"base_uri":"https://localhost:8080/"},"id":"9h5H-7pWUMhe","outputId":"21b122fb-9c1b-47db-ec4f-3e1fb699a09a"},"outputs":[{"name":"stdout","output_type":"stream","text":["Collecting gluonts\n","  Downloading gluonts-0.15.1-py3-none-any.whl (1.5 MB)\n","\u001b[?25l     \u001b[90m━━━━━━━━━━━━━━━━━━━━━━━━━━━━━━━━━━━━━━━━\u001b[0m \u001b[32m0.0/1.5 MB\u001b[0m \u001b[31m?\u001b[0m eta \u001b[36m-:--:--\u001b[0m\r\u001b[2K     \u001b[91m━━━━\u001b[0m\u001b[90m╺\u001b[0m\u001b[90m━━━━━━━━━━━━━━━━━━━━━━━━━━━━━━━━━━━\u001b[0m \u001b[32m0.2/1.5 MB\u001b[0m \u001b[31m4.3 MB/s\u001b[0m eta \u001b[36m0:00:01\u001b[0m\r\u001b[2K     \u001b[91m━━━━━━━━━━━━━\u001b[0m\u001b[90m╺\u001b[0m\u001b[90m━━━━━━━━━━━━━━━━━━━━━━━━━━\u001b[0m \u001b[32m0.5/1.5 MB\u001b[0m \u001b[31m7.5 MB/s\u001b[0m eta \u001b[36m0:00:01\u001b[0m\r\u001b[2K     \u001b[91m━━━━━━━━━━━━━━━━━━━━━━━━━━\u001b[0m\u001b[90m╺\u001b[0m\u001b[90m━━━━━━━━━━━━━\u001b[0m \u001b[32m1.0/1.5 MB\u001b[0m \u001b[31m9.3 MB/s\u001b[0m eta \u001b[36m0:00:01\u001b[0m\r\u001b[2K     \u001b[91m━━━━━━━━━━━━━━━━━━━━━━━━━━━━━━━━━━━━━━━\u001b[0m\u001b[91m╸\u001b[0m \u001b[32m1.5/1.5 MB\u001b[0m \u001b[31m10.8 MB/s\u001b[0m eta \u001b[36m0:00:01\u001b[0m\r\u001b[2K     \u001b[90m━━━━━━━━━━━━━━━━━━━━━━━━━━━━━━━━━━━━━━━━\u001b[0m \u001b[32m1.5/1.5 MB\u001b[0m \u001b[31m9.8 MB/s\u001b[0m eta \u001b[36m0:00:00\u001b[0m\n","\u001b[?25hRequirement already satisfied: numpy~=1.16 in /usr/local/lib/python3.10/dist-packages (from gluonts) (1.25.2)\n","Requirement already satisfied: pandas\u003c3,\u003e=1.0 in /usr/local/lib/python3.10/dist-packages (from gluonts) (2.0.3)\n","Requirement already satisfied: pydantic\u003c3,\u003e=1.7 in /usr/local/lib/python3.10/dist-packages (from gluonts) (2.7.4)\n","Requirement already satisfied: tqdm~=4.23 in /usr/local/lib/python3.10/dist-packages (from gluonts) (4.66.4)\n","Requirement already satisfied: toolz~=0.10 in /usr/local/lib/python3.10/dist-packages (from gluonts) (0.12.1)\n","Requirement already satisfied: typing-extensions~=4.0 in /usr/local/lib/python3.10/dist-packages (from gluonts) (4.12.2)\n","Requirement already satisfied: python-dateutil\u003e=2.8.2 in /usr/local/lib/python3.10/dist-packages (from pandas\u003c3,\u003e=1.0-\u003egluonts) (2.8.2)\n","Requirement already satisfied: pytz\u003e=2020.1 in /usr/local/lib/python3.10/dist-packages (from pandas\u003c3,\u003e=1.0-\u003egluonts) (2023.4)\n","Requirement already satisfied: tzdata\u003e=2022.1 in /usr/local/lib/python3.10/dist-packages (from pandas\u003c3,\u003e=1.0-\u003egluonts) (2024.1)\n","Requirement already satisfied: annotated-types\u003e=0.4.0 in /usr/local/lib/python3.10/dist-packages (from pydantic\u003c3,\u003e=1.7-\u003egluonts) (0.7.0)\n","Requirement already satisfied: pydantic-core==2.18.4 in /usr/local/lib/python3.10/dist-packages (from pydantic\u003c3,\u003e=1.7-\u003egluonts) (2.18.4)\n","Requirement already satisfied: six\u003e=1.5 in /usr/local/lib/python3.10/dist-packages (from python-dateutil\u003e=2.8.2-\u003epandas\u003c3,\u003e=1.0-\u003egluonts) (1.16.0)\n","Installing collected packages: gluonts\n"]}],"source":["pip install gluonts"]},{"cell_type":"code","execution_count":null,"metadata":{"colab":{"background_save":true},"id":"Y4eeRyDmdkfr"},"outputs":[{"name":"stderr","output_type":"stream","text":["ERROR:root:Internal Python error in the inspect module.\n","Below is the traceback from this internal error.\n","\n","ERROR:root:Internal Python error in the inspect module.\n","Below is the traceback from this internal error.\n","\n","ERROR:root:Internal Python error in the inspect module.\n","Below is the traceback from this internal error.\n","\n"]},{"name":"stdout","output_type":"stream","text":["Mounted at /content/drive\n","Traceback (most recent call last):\n","  File \"/usr/local/lib/python3.10/dist-packages/IPython/core/interactiveshell.py\", line 3553, in run_code\n","    exec(code_obj, self.user_global_ns, self.user_ns)\n","  File \"\u003cipython-input-6-08675b0f9a61\u003e\", line 3, in \u003ccell line: 3\u003e\n","    get_ipython().run_line_magic('cd', '/content/drive/MyDrive/TFG_Training_T/T15')\n","  File \"/usr/local/lib/python3.10/dist-packages/IPython/core/interactiveshell.py\", line 2418, in run_line_magic\n","    result = fn(*args, **kwargs)\n","  File \"\u003cdecorator-gen-85\u003e\", line 2, in cd\n","  File \"/usr/local/lib/python3.10/dist-packages/IPython/core/magic.py\", line 187, in \u003clambda\u003e\n","    call = lambda f, *a, **k: f(*a, **k)\n","  File \"/usr/local/lib/python3.10/dist-packages/IPython/core/magics/osm.py\", line 342, in cd\n","    oldcwd = os.getcwd()\n","OSError: [Errno 107] Transport endpoint is not connected\n","\n","During handling of the above exception, another exception occurred:\n","\n","Traceback (most recent call last):\n","  File \"/usr/local/lib/python3.10/dist-packages/IPython/core/interactiveshell.py\", line 2099, in showtraceback\n","    stb = value._render_traceback_()\n","AttributeError: 'OSError' object has no attribute '_render_traceback_'\n","\n","During handling of the above exception, another exception occurred:\n","\n","Traceback (most recent call last):\n","  File \"/usr/local/lib/python3.10/dist-packages/IPython/core/ultratb.py\", line 1101, in get_records\n","    return _fixed_getinnerframes(etb, number_of_lines_of_context, tb_offset)\n","  File \"/usr/local/lib/python3.10/dist-packages/IPython/core/ultratb.py\", line 248, in wrapped\n","    return f(*args, **kwargs)\n","  File \"/usr/local/lib/python3.10/dist-packages/IPython/core/ultratb.py\", line 281, in _fixed_getinnerframes\n","    records = fix_frame_records_filenames(inspect.getinnerframes(etb, context))\n","  File \"/usr/lib/python3.10/inspect.py\", line 1662, in getinnerframes\n","    frameinfo = (tb.tb_frame,) + getframeinfo(tb, context)\n","  File \"/usr/lib/python3.10/inspect.py\", line 1620, in getframeinfo\n","    filename = getsourcefile(frame) or getfile(frame)\n","  File \"/usr/lib/python3.10/inspect.py\", line 829, in getsourcefile\n","    module = getmodule(object, filename)\n","  File \"/usr/lib/python3.10/inspect.py\", line 861, in getmodule\n","    file = getabsfile(object, _filename)\n","  File \"/usr/lib/python3.10/inspect.py\", line 845, in getabsfile\n","    return os.path.normcase(os.path.abspath(_filename))\n","  File \"/usr/lib/python3.10/posixpath.py\", line 384, in abspath\n","    cwd = os.getcwd()\n","OSError: [Errno 107] Transport endpoint is not connected\n","Traceback (most recent call last):\n","  File \"/usr/local/lib/python3.10/dist-packages/IPython/core/interactiveshell.py\", line 3553, in run_code\n","    exec(code_obj, self.user_global_ns, self.user_ns)\n","  File \"\u003cipython-input-6-08675b0f9a61\u003e\", line 3, in \u003ccell line: 3\u003e\n","    get_ipython().run_line_magic('cd', '/content/drive/MyDrive/TFG_Training_T/T15')\n","  File \"/usr/local/lib/python3.10/dist-packages/IPython/core/interactiveshell.py\", line 2418, in run_line_magic\n","    result = fn(*args, **kwargs)\n","  File \"\u003cdecorator-gen-85\u003e\", line 2, in cd\n","  File \"/usr/local/lib/python3.10/dist-packages/IPython/core/magic.py\", line 187, in \u003clambda\u003e\n","    call = lambda f, *a, **k: f(*a, **k)\n","  File \"/usr/local/lib/python3.10/dist-packages/IPython/core/magics/osm.py\", line 342, in cd\n","    oldcwd = os.getcwd()\n","OSError: [Errno 107] Transport endpoint is not connected\n","\n","During handling of the above exception, another exception occurred:\n","\n","Traceback (most recent call last):\n","  File \"/usr/local/lib/python3.10/dist-packages/IPython/core/interactiveshell.py\", line 2099, in showtraceback\n","    stb = value._render_traceback_()\n","AttributeError: 'OSError' object has no attribute '_render_traceback_'\n","\n","During handling of the above exception, another exception occurred:\n","\n","Traceback (most recent call last):\n","  File \"/usr/local/lib/python3.10/dist-packages/IPython/core/interactiveshell.py\", line 3473, in run_ast_nodes\n","    if (await self.run_code(code, result,  async_=asy)):\n","  File \"/usr/local/lib/python3.10/dist-packages/IPython/core/interactiveshell.py\", line 3575, in run_code\n","    self.showtraceback(running_compiled_code=True)\n","  File \"/usr/local/lib/python3.10/dist-packages/IPython/core/interactiveshell.py\", line 2101, in showtraceback\n","    stb = self.InteractiveTB.structured_traceback(etype,\n","  File \"/usr/local/lib/python3.10/dist-packages/IPython/core/ultratb.py\", line 1367, in structured_traceback\n","    return FormattedTB.structured_traceback(\n","  File \"/usr/local/lib/python3.10/dist-packages/IPython/core/ultratb.py\", line 1267, in structured_traceback\n","    return VerboseTB.structured_traceback(\n","  File \"/usr/local/lib/python3.10/dist-packages/IPython/core/ultratb.py\", line 1124, in structured_traceback\n","    formatted_exception = self.format_exception_as_a_whole(etype, evalue, etb, number_of_lines_of_context,\n","  File \"/usr/local/lib/python3.10/dist-packages/IPython/core/ultratb.py\", line 1082, in format_exception_as_a_whole\n","    last_unique, recursion_repeat = find_recursion(orig_etype, evalue, records)\n","  File \"/usr/local/lib/python3.10/dist-packages/IPython/core/ultratb.py\", line 382, in find_recursion\n","    return len(records), 0\n","TypeError: object of type 'NoneType' has no len()\n","\n","During handling of the above exception, another exception occurred:\n","\n","Traceback (most recent call last):\n","  File \"/usr/local/lib/python3.10/dist-packages/IPython/core/interactiveshell.py\", line 2099, in showtraceback\n","    stb = value._render_traceback_()\n","AttributeError: 'TypeError' object has no attribute '_render_traceback_'\n","\n","During handling of the above exception, another exception occurred:\n","\n","Traceback (most recent call last):\n","  File \"/usr/local/lib/python3.10/dist-packages/IPython/core/ultratb.py\", line 1101, in get_records\n","    return _fixed_getinnerframes(etb, number_of_lines_of_context, tb_offset)\n","  File \"/usr/local/lib/python3.10/dist-packages/IPython/core/ultratb.py\", line 248, in wrapped\n","    return f(*args, **kwargs)\n","  File \"/usr/local/lib/python3.10/dist-packages/IPython/core/ultratb.py\", line 281, in _fixed_getinnerframes\n","    records = fix_frame_records_filenames(inspect.getinnerframes(etb, context))\n","  File \"/usr/lib/python3.10/inspect.py\", line 1662, in getinnerframes\n","    frameinfo = (tb.tb_frame,) + getframeinfo(tb, context)\n","  File \"/usr/lib/python3.10/inspect.py\", line 1620, in getframeinfo\n","    filename = getsourcefile(frame) or getfile(frame)\n","  File \"/usr/lib/python3.10/inspect.py\", line 829, in getsourcefile\n","    module = getmodule(object, filename)\n","  File \"/usr/lib/python3.10/inspect.py\", line 861, in getmodule\n","    file = getabsfile(object, _filename)\n","  File \"/usr/lib/python3.10/inspect.py\", line 845, in getabsfile\n","    return os.path.normcase(os.path.abspath(_filename))\n","  File \"/usr/lib/python3.10/posixpath.py\", line 384, in abspath\n","    cwd = os.getcwd()\n","OSError: [Errno 107] Transport endpoint is not connected\n","Traceback (most recent call last):\n","  File \"/usr/local/lib/python3.10/dist-packages/IPython/core/interactiveshell.py\", line 3553, in run_code\n","    exec(code_obj, self.user_global_ns, self.user_ns)\n","  File \"\u003cipython-input-6-08675b0f9a61\u003e\", line 3, in \u003ccell line: 3\u003e\n","    get_ipython().run_line_magic('cd', '/content/drive/MyDrive/TFG_Training_T/T15')\n","  File \"/usr/local/lib/python3.10/dist-packages/IPython/core/interactiveshell.py\", line 2418, in run_line_magic\n","    result = fn(*args, **kwargs)\n","  File \"\u003cdecorator-gen-85\u003e\", line 2, in cd\n","  File \"/usr/local/lib/python3.10/dist-packages/IPython/core/magic.py\", line 187, in \u003clambda\u003e\n","    call = lambda f, *a, **k: f(*a, **k)\n","  File \"/usr/local/lib/python3.10/dist-packages/IPython/core/magics/osm.py\", line 342, in cd\n","    oldcwd = os.getcwd()\n","OSError: [Errno 107] Transport endpoint is not connected\n","\n","During handling of the above exception, another exception occurred:\n","\n","Traceback (most recent call last):\n","  File \"/usr/local/lib/python3.10/dist-packages/IPython/core/interactiveshell.py\", line 2099, in showtraceback\n","    stb = value._render_traceback_()\n","AttributeError: 'OSError' object has no attribute '_render_traceback_'\n","\n","During handling of the above exception, another exception occurred:\n","\n","Traceback (most recent call last):\n","  File \"/usr/local/lib/python3.10/dist-packages/IPython/core/interactiveshell.py\", line 3473, in run_ast_nodes\n","    if (await self.run_code(code, result,  async_=asy)):\n","  File \"/usr/local/lib/python3.10/dist-packages/IPython/core/interactiveshell.py\", line 3575, in run_code\n","    self.showtraceback(running_compiled_code=True)\n","  File \"/usr/local/lib/python3.10/dist-packages/IPython/core/interactiveshell.py\", line 2101, in showtraceback\n","    stb = self.InteractiveTB.structured_traceback(etype,\n","  File \"/usr/local/lib/python3.10/dist-packages/IPython/core/ultratb.py\", line 1367, in structured_traceback\n","    return FormattedTB.structured_traceback(\n","  File \"/usr/local/lib/python3.10/dist-packages/IPython/core/ultratb.py\", line 1267, in structured_traceback\n","    return VerboseTB.structured_traceback(\n","  File \"/usr/local/lib/python3.10/dist-packages/IPython/core/ultratb.py\", line 1124, in structured_traceback\n","    formatted_exception = self.format_exception_as_a_whole(etype, evalue, etb, number_of_lines_of_context,\n","  File \"/usr/local/lib/python3.10/dist-packages/IPython/core/ultratb.py\", line 1082, in format_exception_as_a_whole\n","    last_unique, recursion_repeat = find_recursion(orig_etype, evalue, records)\n","  File \"/usr/local/lib/python3.10/dist-packages/IPython/core/ultratb.py\", line 382, in find_recursion\n","    return len(records), 0\n","TypeError: object of type 'NoneType' has no len()\n","\n","During handling of the above exception, another exception occurred:\n","\n","Traceback (most recent call last):\n","  File \"/usr/local/lib/python3.10/dist-packages/IPython/core/interactiveshell.py\", line 2099, in showtraceback\n","    stb = value._render_traceback_()\n","AttributeError: 'TypeError' object has no attribute '_render_traceback_'\n","\n","During handling of the above exception, another exception occurred:\n","\n","Traceback (most recent call last):\n","  File \"/usr/local/lib/python3.10/dist-packages/IPython/core/interactiveshell.py\", line 3030, in _run_cell\n","    return runner(coro)\n","  File \"/usr/local/lib/python3.10/dist-packages/IPython/core/async_helpers.py\", line 78, in _pseudo_sync_runner\n","    coro.send(None)\n","  File \"/usr/local/lib/python3.10/dist-packages/IPython/core/interactiveshell.py\", line 3257, in run_cell_async\n","    has_raised = await self.run_ast_nodes(code_ast.body, cell_name,\n","  File \"/usr/local/lib/python3.10/dist-packages/IPython/core/interactiveshell.py\", line 3492, in run_ast_nodes\n","    self.showtraceback()\n","  File \"/usr/local/lib/python3.10/dist-packages/IPython/core/interactiveshell.py\", line 2101, in showtraceback\n","    stb = self.InteractiveTB.structured_traceback(etype,\n","  File \"/usr/local/lib/python3.10/dist-packages/IPython/core/ultratb.py\", line 1367, in structured_traceback\n","    return FormattedTB.structured_traceback(\n","  File \"/usr/local/lib/python3.10/dist-packages/IPython/core/ultratb.py\", line 1267, in structured_traceback\n","    return VerboseTB.structured_traceback(\n","  File \"/usr/local/lib/python3.10/dist-packages/IPython/core/ultratb.py\", line 1142, in structured_traceback\n","    formatted_exceptions += self.format_exception_as_a_whole(etype, evalue, etb, lines_of_context,\n","  File \"/usr/local/lib/python3.10/dist-packages/IPython/core/ultratb.py\", line 1082, in format_exception_as_a_whole\n","    last_unique, recursion_repeat = find_recursion(orig_etype, evalue, records)\n","  File \"/usr/local/lib/python3.10/dist-packages/IPython/core/ultratb.py\", line 382, in find_recursion\n","    return len(records), 0\n","TypeError: object of type 'NoneType' has no len()\n","\n","During handling of the above exception, another exception occurred:\n","\n","Traceback (most recent call last):\n","  File \"/usr/local/lib/python3.10/dist-packages/IPython/core/interactiveshell.py\", line 2099, in showtraceback\n","    stb = value._render_traceback_()\n","AttributeError: 'TypeError' object has no attribute '_render_traceback_'\n","\n","During handling of the above exception, another exception occurred:\n","\n","Traceback (most recent call last):\n","  File \"/usr/local/lib/python3.10/dist-packages/IPython/core/ultratb.py\", line 1101, in get_records\n","    return _fixed_getinnerframes(etb, number_of_lines_of_context, tb_offset)\n","  File \"/usr/local/lib/python3.10/dist-packages/IPython/core/ultratb.py\", line 248, in wrapped\n","    return f(*args, **kwargs)\n","  File \"/usr/local/lib/python3.10/dist-packages/IPython/core/ultratb.py\", line 281, in _fixed_getinnerframes\n","    records = fix_frame_records_filenames(inspect.getinnerframes(etb, context))\n","  File \"/usr/lib/python3.10/inspect.py\", line 1662, in getinnerframes\n","    frameinfo = (tb.tb_frame,) + getframeinfo(tb, context)\n","  File \"/usr/lib/python3.10/inspect.py\", line 1620, in getframeinfo\n","    filename = getsourcefile(frame) or getfile(frame)\n","  File \"/usr/lib/python3.10/inspect.py\", line 829, in getsourcefile\n","    module = getmodule(object, filename)\n","  File \"/usr/lib/python3.10/inspect.py\", line 861, in getmodule\n","    file = getabsfile(object, _filename)\n","  File \"/usr/lib/python3.10/inspect.py\", line 845, in getabsfile\n","    return os.path.normcase(os.path.abspath(_filename))\n","  File \"/usr/lib/python3.10/posixpath.py\", line 384, in abspath\n","    cwd = os.getcwd()\n","OSError: [Errno 107] Transport endpoint is not connected\n"]}],"source":["from google.colab import drive\n","drive.mount(\"/content/drive\", force_remount=True)\n","%cd /content/drive/MyDrive/TFG_Training_T/T15\n","!python main.py"]}],"metadata":{"accelerator":"GPU","colab":{"gpuType":"T4","name":"","version":""},"kernelspec":{"display_name":"Python 3","name":"python3"},"language_info":{"name":"python"}},"nbformat":4,"nbformat_minor":0}