{"cells":[{"cell_type":"code","execution_count":null,"metadata":{"colab":{"base_uri":"https://localhost:8080/"},"executionInfo":{"elapsed":19561,"status":"ok","timestamp":1720129768884,"user":{"displayName":"Pilar Raquel Hernández Galayo","userId":"01479152070189086334"},"user_tz":-120},"id":"SuKs3ewFvO2p","outputId":"d4bdaa6a-2635-4822-8daf-563ed974b612"},"outputs":[{"name":"stdout","output_type":"stream","text":["Collecting datasets\n","  Downloading datasets-2.20.0-py3-none-any.whl (547 kB)\n","\u001b[?25l     \u001b[90m━━━━━━━━━━━━━━━━━━━━━━━━━━━━━━━━━━━━━━━━\u001b[0m \u001b[32m0.0/547.8 kB\u001b[0m \u001b[31m?\u001b[0m eta \u001b[36m-:--:--\u001b[0m\r\u001b[2K     \u001b[91m━━━━━━━━\u001b[0m\u001b[90m╺\u001b[0m\u001b[90m━━━━━━━━━━━━━━━━━━━━━━━━━━━━━━━\u001b[0m \u001b[32m112.6/547.8 kB\u001b[0m \u001b[31m3.0 MB/s\u001b[0m eta \u001b[36m0:00:01\u001b[0m\r\u001b[2K     \u001b[91m━━━━━━━━━━━━━━━━━━━━━━━━━━━━━━━━━━━━━━━\u001b[0m\u001b[91m╸\u001b[0m \u001b[32m542.7/547.8 kB\u001b[0m \u001b[31m9.0 MB/s\u001b[0m eta \u001b[36m0:00:01\u001b[0m\r\u001b[2K     \u001b[90m━━━━━━━━━━━━━━━━━━━━━━━━━━━━━━━━━━━━━━━━\u001b[0m \u001b[32m547.8/547.8 kB\u001b[0m \u001b[31m7.2 MB/s\u001b[0m eta \u001b[36m0:00:00\u001b[0m\n","\u001b[?25hRequirement already satisfied: filelock in /usr/local/lib/python3.10/dist-packages (from datasets) (3.15.4)\n","Requirement already satisfied: numpy\u003e=1.17 in /usr/local/lib/python3.10/dist-packages (from datasets) (1.25.2)\n","Collecting pyarrow\u003e=15.0.0 (from datasets)\n","  Downloading pyarrow-16.1.0-cp310-cp310-manylinux_2_28_x86_64.whl (40.8 MB)\n","\u001b[2K     \u001b[90m━━━━━━━━━━━━━━━━━━━━━━━━━━━━━━━━━━━━━━━━\u001b[0m \u001b[32m40.8/40.8 MB\u001b[0m \u001b[31m9.5 MB/s\u001b[0m eta \u001b[36m0:00:00\u001b[0m\n","\u001b[?25hRequirement already satisfied: pyarrow-hotfix in /usr/local/lib/python3.10/dist-packages (from datasets) (0.6)\n","Collecting dill\u003c0.3.9,\u003e=0.3.0 (from datasets)\n","  Downloading dill-0.3.8-py3-none-any.whl (116 kB)\n","\u001b[2K     \u001b[90m━━━━━━━━━━━━━━━━━━━━━━━━━━━━━━━━━━━━━━━━\u001b[0m \u001b[32m116.3/116.3 kB\u001b[0m \u001b[31m6.9 MB/s\u001b[0m eta \u001b[36m0:00:00\u001b[0m\n","\u001b[?25hRequirement already satisfied: pandas in /usr/local/lib/python3.10/dist-packages (from datasets) (2.0.3)\n","Collecting requests\u003e=2.32.2 (from datasets)\n","  Downloading requests-2.32.3-py3-none-any.whl (64 kB)\n","\u001b[2K     \u001b[90m━━━━━━━━━━━━━━━━━━━━━━━━━━━━━━━━━━━━━━━━\u001b[0m \u001b[32m64.9/64.9 kB\u001b[0m \u001b[31m1.0 MB/s\u001b[0m eta \u001b[36m0:00:00\u001b[0m\n","\u001b[?25hRequirement already satisfied: tqdm\u003e=4.66.3 in /usr/local/lib/python3.10/dist-packages (from datasets) (4.66.4)\n","Collecting xxhash (from datasets)\n","  Downloading xxhash-3.4.1-cp310-cp310-manylinux_2_17_x86_64.manylinux2014_x86_64.whl (194 kB)\n","\u001b[2K     \u001b[90m━━━━━━━━━━━━━━━━━━━━━━━━━━━━━━━━━━━━━━━━\u001b[0m \u001b[32m194.1/194.1 kB\u001b[0m \u001b[31m9.8 MB/s\u001b[0m eta \u001b[36m0:00:00\u001b[0m\n","\u001b[?25hCollecting multiprocess (from datasets)\n","  Downloading multiprocess-0.70.16-py310-none-any.whl (134 kB)\n","\u001b[2K     \u001b[90m━━━━━━━━━━━━━━━━━━━━━━━━━━━━━━━━━━━━━━━━\u001b[0m \u001b[32m134.8/134.8 kB\u001b[0m \u001b[31m7.7 MB/s\u001b[0m eta \u001b[36m0:00:00\u001b[0m\n","\u001b[?25hRequirement already satisfied: fsspec[http]\u003c=2024.5.0,\u003e=2023.1.0 in /usr/local/lib/python3.10/dist-packages (from datasets) (2023.6.0)\n","Requirement already satisfied: aiohttp in /usr/local/lib/python3.10/dist-packages (from datasets) (3.9.5)\n","Requirement already satisfied: huggingface-hub\u003e=0.21.2 in /usr/local/lib/python3.10/dist-packages (from datasets) (0.23.4)\n","Requirement already satisfied: packaging in /usr/local/lib/python3.10/dist-packages (from datasets) (24.1)\n","Requirement already satisfied: pyyaml\u003e=5.1 in /usr/local/lib/python3.10/dist-packages (from datasets) (6.0.1)\n","Requirement already satisfied: aiosignal\u003e=1.1.2 in /usr/local/lib/python3.10/dist-packages (from aiohttp-\u003edatasets) (1.3.1)\n","Requirement already satisfied: attrs\u003e=17.3.0 in /usr/local/lib/python3.10/dist-packages (from aiohttp-\u003edatasets) (23.2.0)\n","Requirement already satisfied: frozenlist\u003e=1.1.1 in /usr/local/lib/python3.10/dist-packages (from aiohttp-\u003edatasets) (1.4.1)\n","Requirement already satisfied: multidict\u003c7.0,\u003e=4.5 in /usr/local/lib/python3.10/dist-packages (from aiohttp-\u003edatasets) (6.0.5)\n","Requirement already satisfied: yarl\u003c2.0,\u003e=1.0 in /usr/local/lib/python3.10/dist-packages (from aiohttp-\u003edatasets) (1.9.4)\n","Requirement already satisfied: async-timeout\u003c5.0,\u003e=4.0 in /usr/local/lib/python3.10/dist-packages (from aiohttp-\u003edatasets) (4.0.3)\n","Requirement already satisfied: typing-extensions\u003e=3.7.4.3 in /usr/local/lib/python3.10/dist-packages (from huggingface-hub\u003e=0.21.2-\u003edatasets) (4.12.2)\n","Requirement already satisfied: charset-normalizer\u003c4,\u003e=2 in /usr/local/lib/python3.10/dist-packages (from requests\u003e=2.32.2-\u003edatasets) (3.3.2)\n","Requirement already satisfied: idna\u003c4,\u003e=2.5 in /usr/local/lib/python3.10/dist-packages (from requests\u003e=2.32.2-\u003edatasets) (3.7)\n","Requirement already satisfied: urllib3\u003c3,\u003e=1.21.1 in /usr/local/lib/python3.10/dist-packages (from requests\u003e=2.32.2-\u003edatasets) (2.0.7)\n","Requirement already satisfied: certifi\u003e=2017.4.17 in /usr/local/lib/python3.10/dist-packages (from requests\u003e=2.32.2-\u003edatasets) (2024.6.2)\n","Requirement already satisfied: python-dateutil\u003e=2.8.2 in /usr/local/lib/python3.10/dist-packages (from pandas-\u003edatasets) (2.8.2)\n","Requirement already satisfied: pytz\u003e=2020.1 in /usr/local/lib/python3.10/dist-packages (from pandas-\u003edatasets) (2023.4)\n","Requirement already satisfied: tzdata\u003e=2022.1 in /usr/local/lib/python3.10/dist-packages (from pandas-\u003edatasets) (2024.1)\n","Requirement already satisfied: six\u003e=1.5 in /usr/local/lib/python3.10/dist-packages (from python-dateutil\u003e=2.8.2-\u003epandas-\u003edatasets) (1.16.0)\n","Installing collected packages: xxhash, requests, pyarrow, dill, multiprocess, datasets\n","  Attempting uninstall: requests\n","    Found existing installation: requests 2.31.0\n","    Uninstalling requests-2.31.0:\n","      Successfully uninstalled requests-2.31.0\n","  Attempting uninstall: pyarrow\n","    Found existing installation: pyarrow 14.0.2\n","    Uninstalling pyarrow-14.0.2:\n","      Successfully uninstalled pyarrow-14.0.2\n","\u001b[31mERROR: pip's dependency resolver does not currently take into account all the packages that are installed. This behaviour is the source of the following dependency conflicts.\n","cudf-cu12 24.4.1 requires pyarrow\u003c15.0.0a0,\u003e=14.0.1, but you have pyarrow 16.1.0 which is incompatible.\n","google-colab 1.0.0 requires requests==2.31.0, but you have requests 2.32.3 which is incompatible.\n","ibis-framework 8.0.0 requires pyarrow\u003c16,\u003e=2, but you have pyarrow 16.1.0 which is incompatible.\u001b[0m\u001b[31m\n","\u001b[0mSuccessfully installed datasets-2.20.0 dill-0.3.8 multiprocess-0.70.16 pyarrow-16.1.0 requests-2.32.3 xxhash-3.4.1\n"]}],"source":["pip install datasets"]},{"cell_type":"code","execution_count":null,"metadata":{"colab":{"base_uri":"https://localhost:8080/"},"id":"x53r72kYUIac","outputId":"b5769670-9fc7-48ab-add9-0b35ced6e879"},"outputs":[{"name":"stdout","output_type":"stream","text":["Collecting accelerate\n","  Downloading accelerate-0.32.1-py3-none-any.whl (314 kB)\n","\u001b[?25l     \u001b[90m━━━━━━━━━━━━━━━━━━━━━━━━━━━━━━━━━━━━━━━━\u001b[0m \u001b[32m0.0/314.1 kB\u001b[0m \u001b[31m?\u001b[0m eta \u001b[36m-:--:--\u001b[0m\r\u001b[2K     \u001b[91m━━━━━━━━━━━━━━\u001b[0m\u001b[90m╺\u001b[0m\u001b[90m━━━━━━━━━━━━━━━━━━━━━━━━━\u001b[0m \u001b[32m112.6/314.1 kB\u001b[0m \u001b[31m3.4 MB/s\u001b[0m eta \u001b[36m0:00:01\u001b[0m\r\u001b[2K     \u001b[90m━━━━━━━━━━━━━━━━━━━━━━━━━━━━━━━━━━━━━━━━\u001b[0m \u001b[32m314.1/314.1 kB\u001b[0m \u001b[31m5.8 MB/s\u001b[0m eta \u001b[36m0:00:00\u001b[0m\n","\u001b[?25hRequirement already satisfied: numpy\u003c2.0.0,\u003e=1.17 in /usr/local/lib/python3.10/dist-packages (from accelerate) (1.25.2)\n","Requirement already satisfied: packaging\u003e=20.0 in /usr/local/lib/python3.10/dist-packages (from accelerate) (24.1)\n","Requirement already satisfied: psutil in /usr/local/lib/python3.10/dist-packages (from accelerate) (5.9.5)\n","Requirement already satisfied: pyyaml in /usr/local/lib/python3.10/dist-packages (from accelerate) (6.0.1)\n","Requirement already satisfied: torch\u003e=1.10.0 in /usr/local/lib/python3.10/dist-packages (from accelerate) (2.3.0+cu121)\n","Requirement already satisfied: huggingface-hub in /usr/local/lib/python3.10/dist-packages (from accelerate) (0.23.4)\n","Requirement already satisfied: safetensors\u003e=0.3.1 in /usr/local/lib/python3.10/dist-packages (from accelerate) (0.4.3)\n","Requirement already satisfied: filelock in /usr/local/lib/python3.10/dist-packages (from torch\u003e=1.10.0-\u003eaccelerate) (3.15.4)\n","Requirement already satisfied: typing-extensions\u003e=4.8.0 in /usr/local/lib/python3.10/dist-packages (from torch\u003e=1.10.0-\u003eaccelerate) (4.12.2)\n","Requirement already satisfied: sympy in /usr/local/lib/python3.10/dist-packages (from torch\u003e=1.10.0-\u003eaccelerate) (1.12.1)\n","Requirement already satisfied: networkx in /usr/local/lib/python3.10/dist-packages (from torch\u003e=1.10.0-\u003eaccelerate) (3.3)\n","Requirement already satisfied: jinja2 in /usr/local/lib/python3.10/dist-packages (from torch\u003e=1.10.0-\u003eaccelerate) (3.1.4)\n","Requirement already satisfied: fsspec in /usr/local/lib/python3.10/dist-packages (from torch\u003e=1.10.0-\u003eaccelerate) (2023.6.0)\n","Collecting nvidia-cuda-nvrtc-cu12==12.1.105 (from torch\u003e=1.10.0-\u003eaccelerate)\n","  Using cached nvidia_cuda_nvrtc_cu12-12.1.105-py3-none-manylinux1_x86_64.whl (23.7 MB)\n","Collecting nvidia-cuda-runtime-cu12==12.1.105 (from torch\u003e=1.10.0-\u003eaccelerate)\n","  Using cached nvidia_cuda_runtime_cu12-12.1.105-py3-none-manylinux1_x86_64.whl (823 kB)\n","Collecting nvidia-cuda-cupti-cu12==12.1.105 (from torch\u003e=1.10.0-\u003eaccelerate)\n","  Using cached nvidia_cuda_cupti_cu12-12.1.105-py3-none-manylinux1_x86_64.whl (14.1 MB)\n","Collecting nvidia-cudnn-cu12==8.9.2.26 (from torch\u003e=1.10.0-\u003eaccelerate)\n","  Using cached nvidia_cudnn_cu12-8.9.2.26-py3-none-manylinux1_x86_64.whl (731.7 MB)\n"]}],"source":["pip install accelerate"]},{"cell_type":"code","execution_count":null,"metadata":{"id":"DjDsEzuAUKOb"},"outputs":[],"source":["pip install evaluate"]},{"cell_type":"code","execution_count":null,"metadata":{"id":"9h5H-7pWUMhe"},"outputs":[],"source":["pip install gluonts"]},{"cell_type":"code","execution_count":null,"metadata":{"colab":{"background_save":true},"id":"Y4eeRyDmdkfr"},"outputs":[{"name":"stderr","output_type":"stream","text":["ERROR:root:Internal Python error in the inspect module.\n","Below is the traceback from this internal error.\n","\n","ERROR:root:Internal Python error in the inspect module.\n","Below is the traceback from this internal error.\n","\n","ERROR:root:Internal Python error in the inspect module.\n","Below is the traceback from this internal error.\n","\n"]},{"name":"stdout","output_type":"stream","text":["Mounted at /content/drive\n","Traceback (most recent call last):\n","  File \"/usr/local/lib/python3.10/dist-packages/IPython/core/interactiveshell.py\", line 3553, in run_code\n","    exec(code_obj, self.user_global_ns, self.user_ns)\n","  File \"\u003cipython-input-6-f48b0f2c1aaa\u003e\", line 3, in \u003ccell line: 3\u003e\n","    get_ipython().run_line_magic('cd', '/content/drive/MyDrive/TFG_Training_T/A3')\n","  File \"/usr/local/lib/python3.10/dist-packages/IPython/core/interactiveshell.py\", line 2418, in run_line_magic\n","    result = fn(*args, **kwargs)\n","  File \"\u003cdecorator-gen-85\u003e\", line 2, in cd\n","  File \"/usr/local/lib/python3.10/dist-packages/IPython/core/magic.py\", line 187, in \u003clambda\u003e\n","    call = lambda f, *a, **k: f(*a, **k)\n","  File \"/usr/local/lib/python3.10/dist-packages/IPython/core/magics/osm.py\", line 342, in cd\n","    oldcwd = os.getcwd()\n","OSError: [Errno 107] Transport endpoint is not connected\n","\n","During handling of the above exception, another exception occurred:\n","\n","Traceback (most recent call last):\n","  File \"/usr/local/lib/python3.10/dist-packages/IPython/core/interactiveshell.py\", line 2099, in showtraceback\n","    stb = value._render_traceback_()\n","AttributeError: 'OSError' object has no attribute '_render_traceback_'\n","\n","During handling of the above exception, another exception occurred:\n","\n","Traceback (most recent call last):\n","  File \"/usr/local/lib/python3.10/dist-packages/IPython/core/ultratb.py\", line 1101, in get_records\n","    return _fixed_getinnerframes(etb, number_of_lines_of_context, tb_offset)\n","  File \"/usr/local/lib/python3.10/dist-packages/IPython/core/ultratb.py\", line 248, in wrapped\n","    return f(*args, **kwargs)\n","  File \"/usr/local/lib/python3.10/dist-packages/IPython/core/ultratb.py\", line 281, in _fixed_getinnerframes\n","    records = fix_frame_records_filenames(inspect.getinnerframes(etb, context))\n","  File \"/usr/lib/python3.10/inspect.py\", line 1662, in getinnerframes\n","    frameinfo = (tb.tb_frame,) + getframeinfo(tb, context)\n","  File \"/usr/lib/python3.10/inspect.py\", line 1620, in getframeinfo\n","    filename = getsourcefile(frame) or getfile(frame)\n","  File \"/usr/lib/python3.10/inspect.py\", line 829, in getsourcefile\n","    module = getmodule(object, filename)\n","  File \"/usr/lib/python3.10/inspect.py\", line 861, in getmodule\n","    file = getabsfile(object, _filename)\n","  File \"/usr/lib/python3.10/inspect.py\", line 845, in getabsfile\n","    return os.path.normcase(os.path.abspath(_filename))\n","  File \"/usr/lib/python3.10/posixpath.py\", line 384, in abspath\n","    cwd = os.getcwd()\n","OSError: [Errno 107] Transport endpoint is not connected\n","Traceback (most recent call last):\n","  File \"/usr/local/lib/python3.10/dist-packages/IPython/core/interactiveshell.py\", line 3553, in run_code\n","    exec(code_obj, self.user_global_ns, self.user_ns)\n","  File \"\u003cipython-input-6-f48b0f2c1aaa\u003e\", line 3, in \u003ccell line: 3\u003e\n","    get_ipython().run_line_magic('cd', '/content/drive/MyDrive/TFG_Training_T/A3')\n","  File \"/usr/local/lib/python3.10/dist-packages/IPython/core/interactiveshell.py\", line 2418, in run_line_magic\n","    result = fn(*args, **kwargs)\n","  File \"\u003cdecorator-gen-85\u003e\", line 2, in cd\n","  File \"/usr/local/lib/python3.10/dist-packages/IPython/core/magic.py\", line 187, in \u003clambda\u003e\n","    call = lambda f, *a, **k: f(*a, **k)\n","  File \"/usr/local/lib/python3.10/dist-packages/IPython/core/magics/osm.py\", line 342, in cd\n","    oldcwd = os.getcwd()\n","OSError: [Errno 107] Transport endpoint is not connected\n","\n","During handling of the above exception, another exception occurred:\n","\n","Traceback (most recent call last):\n","  File \"/usr/local/lib/python3.10/dist-packages/IPython/core/interactiveshell.py\", line 2099, in showtraceback\n","    stb = value._render_traceback_()\n","AttributeError: 'OSError' object has no attribute '_render_traceback_'\n","\n","During handling of the above exception, another exception occurred:\n","\n","Traceback (most recent call last):\n","  File \"/usr/local/lib/python3.10/dist-packages/IPython/core/interactiveshell.py\", line 3473, in run_ast_nodes\n","    if (await self.run_code(code, result,  async_=asy)):\n","  File \"/usr/local/lib/python3.10/dist-packages/IPython/core/interactiveshell.py\", line 3575, in run_code\n","    self.showtraceback(running_compiled_code=True)\n","  File \"/usr/local/lib/python3.10/dist-packages/IPython/core/interactiveshell.py\", line 2101, in showtraceback\n","    stb = self.InteractiveTB.structured_traceback(etype,\n","  File \"/usr/local/lib/python3.10/dist-packages/IPython/core/ultratb.py\", line 1367, in structured_traceback\n","    return FormattedTB.structured_traceback(\n","  File \"/usr/local/lib/python3.10/dist-packages/IPython/core/ultratb.py\", line 1267, in structured_traceback\n","    return VerboseTB.structured_traceback(\n","  File \"/usr/local/lib/python3.10/dist-packages/IPython/core/ultratb.py\", line 1124, in structured_traceback\n","    formatted_exception = self.format_exception_as_a_whole(etype, evalue, etb, number_of_lines_of_context,\n","  File \"/usr/local/lib/python3.10/dist-packages/IPython/core/ultratb.py\", line 1082, in format_exception_as_a_whole\n","    last_unique, recursion_repeat = find_recursion(orig_etype, evalue, records)\n","  File \"/usr/local/lib/python3.10/dist-packages/IPython/core/ultratb.py\", line 382, in find_recursion\n","    return len(records), 0\n","TypeError: object of type 'NoneType' has no len()\n","\n","During handling of the above exception, another exception occurred:\n","\n","Traceback (most recent call last):\n","  File \"/usr/local/lib/python3.10/dist-packages/IPython/core/interactiveshell.py\", line 2099, in showtraceback\n","    stb = value._render_traceback_()\n","AttributeError: 'TypeError' object has no attribute '_render_traceback_'\n","\n","During handling of the above exception, another exception occurred:\n","\n","Traceback (most recent call last):\n","  File \"/usr/local/lib/python3.10/dist-packages/IPython/core/ultratb.py\", line 1101, in get_records\n","    return _fixed_getinnerframes(etb, number_of_lines_of_context, tb_offset)\n","  File \"/usr/local/lib/python3.10/dist-packages/IPython/core/ultratb.py\", line 248, in wrapped\n","    return f(*args, **kwargs)\n","  File \"/usr/local/lib/python3.10/dist-packages/IPython/core/ultratb.py\", line 281, in _fixed_getinnerframes\n","    records = fix_frame_records_filenames(inspect.getinnerframes(etb, context))\n","  File \"/usr/lib/python3.10/inspect.py\", line 1662, in getinnerframes\n","    frameinfo = (tb.tb_frame,) + getframeinfo(tb, context)\n","  File \"/usr/lib/python3.10/inspect.py\", line 1620, in getframeinfo\n","    filename = getsourcefile(frame) or getfile(frame)\n","  File \"/usr/lib/python3.10/inspect.py\", line 829, in getsourcefile\n","    module = getmodule(object, filename)\n","  File \"/usr/lib/python3.10/inspect.py\", line 861, in getmodule\n","    file = getabsfile(object, _filename)\n","  File \"/usr/lib/python3.10/inspect.py\", line 845, in getabsfile\n","    return os.path.normcase(os.path.abspath(_filename))\n","  File \"/usr/lib/python3.10/posixpath.py\", line 384, in abspath\n","    cwd = os.getcwd()\n","OSError: [Errno 107] Transport endpoint is not connected\n","Traceback (most recent call last):\n","  File \"/usr/local/lib/python3.10/dist-packages/IPython/core/interactiveshell.py\", line 3553, in run_code\n","    exec(code_obj, self.user_global_ns, self.user_ns)\n","  File \"\u003cipython-input-6-f48b0f2c1aaa\u003e\", line 3, in \u003ccell line: 3\u003e\n","    get_ipython().run_line_magic('cd', '/content/drive/MyDrive/TFG_Training_T/A3')\n","  File \"/usr/local/lib/python3.10/dist-packages/IPython/core/interactiveshell.py\", line 2418, in run_line_magic\n","    result = fn(*args, **kwargs)\n","  File \"\u003cdecorator-gen-85\u003e\", line 2, in cd\n","  File \"/usr/local/lib/python3.10/dist-packages/IPython/core/magic.py\", line 187, in \u003clambda\u003e\n","    call = lambda f, *a, **k: f(*a, **k)\n","  File \"/usr/local/lib/python3.10/dist-packages/IPython/core/magics/osm.py\", line 342, in cd\n","    oldcwd = os.getcwd()\n","OSError: [Errno 107] Transport endpoint is not connected\n","\n","During handling of the above exception, another exception occurred:\n","\n","Traceback (most recent call last):\n","  File \"/usr/local/lib/python3.10/dist-packages/IPython/core/interactiveshell.py\", line 2099, in showtraceback\n","    stb = value._render_traceback_()\n","AttributeError: 'OSError' object has no attribute '_render_traceback_'\n","\n","During handling of the above exception, another exception occurred:\n","\n","Traceback (most recent call last):\n","  File \"/usr/local/lib/python3.10/dist-packages/IPython/core/interactiveshell.py\", line 3473, in run_ast_nodes\n","    if (await self.run_code(code, result,  async_=asy)):\n","  File \"/usr/local/lib/python3.10/dist-packages/IPython/core/interactiveshell.py\", line 3575, in run_code\n","    self.showtraceback(running_compiled_code=True)\n","  File \"/usr/local/lib/python3.10/dist-packages/IPython/core/interactiveshell.py\", line 2101, in showtraceback\n","    stb = self.InteractiveTB.structured_traceback(etype,\n","  File \"/usr/local/lib/python3.10/dist-packages/IPython/core/ultratb.py\", line 1367, in structured_traceback\n","    return FormattedTB.structured_traceback(\n","  File \"/usr/local/lib/python3.10/dist-packages/IPython/core/ultratb.py\", line 1267, in structured_traceback\n","    return VerboseTB.structured_traceback(\n","  File \"/usr/local/lib/python3.10/dist-packages/IPython/core/ultratb.py\", line 1124, in structured_traceback\n","    formatted_exception = self.format_exception_as_a_whole(etype, evalue, etb, number_of_lines_of_context,\n","  File \"/usr/local/lib/python3.10/dist-packages/IPython/core/ultratb.py\", line 1082, in format_exception_as_a_whole\n","    last_unique, recursion_repeat = find_recursion(orig_etype, evalue, records)\n","  File \"/usr/local/lib/python3.10/dist-packages/IPython/core/ultratb.py\", line 382, in find_recursion\n","    return len(records), 0\n","TypeError: object of type 'NoneType' has no len()\n","\n","During handling of the above exception, another exception occurred:\n","\n","Traceback (most recent call last):\n","  File \"/usr/local/lib/python3.10/dist-packages/IPython/core/interactiveshell.py\", line 2099, in showtraceback\n","    stb = value._render_traceback_()\n","AttributeError: 'TypeError' object has no attribute '_render_traceback_'\n","\n","During handling of the above exception, another exception occurred:\n","\n","Traceback (most recent call last):\n","  File \"/usr/local/lib/python3.10/dist-packages/IPython/core/interactiveshell.py\", line 3030, in _run_cell\n","    return runner(coro)\n","  File \"/usr/local/lib/python3.10/dist-packages/IPython/core/async_helpers.py\", line 78, in _pseudo_sync_runner\n","    coro.send(None)\n","  File \"/usr/local/lib/python3.10/dist-packages/IPython/core/interactiveshell.py\", line 3257, in run_cell_async\n","    has_raised = await self.run_ast_nodes(code_ast.body, cell_name,\n","  File \"/usr/local/lib/python3.10/dist-packages/IPython/core/interactiveshell.py\", line 3492, in run_ast_nodes\n","    self.showtraceback()\n","  File \"/usr/local/lib/python3.10/dist-packages/IPython/core/interactiveshell.py\", line 2101, in showtraceback\n","    stb = self.InteractiveTB.structured_traceback(etype,\n","  File \"/usr/local/lib/python3.10/dist-packages/IPython/core/ultratb.py\", line 1367, in structured_traceback\n","    return FormattedTB.structured_traceback(\n","  File \"/usr/local/lib/python3.10/dist-packages/IPython/core/ultratb.py\", line 1267, in structured_traceback\n","    return VerboseTB.structured_traceback(\n","  File \"/usr/local/lib/python3.10/dist-packages/IPython/core/ultratb.py\", line 1142, in structured_traceback\n","    formatted_exceptions += self.format_exception_as_a_whole(etype, evalue, etb, lines_of_context,\n","  File \"/usr/local/lib/python3.10/dist-packages/IPython/core/ultratb.py\", line 1082, in format_exception_as_a_whole\n","    last_unique, recursion_repeat = find_recursion(orig_etype, evalue, records)\n","  File \"/usr/local/lib/python3.10/dist-packages/IPython/core/ultratb.py\", line 382, in find_recursion\n","    return len(records), 0\n","TypeError: object of type 'NoneType' has no len()\n","\n","During handling of the above exception, another exception occurred:\n","\n","Traceback (most recent call last):\n","  File \"/usr/local/lib/python3.10/dist-packages/IPython/core/interactiveshell.py\", line 2099, in showtraceback\n","    stb = value._render_traceback_()\n","AttributeError: 'TypeError' object has no attribute '_render_traceback_'\n","\n","During handling of the above exception, another exception occurred:\n","\n","Traceback (most recent call last):\n","  File \"/usr/local/lib/python3.10/dist-packages/IPython/core/ultratb.py\", line 1101, in get_records\n","    return _fixed_getinnerframes(etb, number_of_lines_of_context, tb_offset)\n","  File \"/usr/local/lib/python3.10/dist-packages/IPython/core/ultratb.py\", line 248, in wrapped\n","    return f(*args, **kwargs)\n","  File \"/usr/local/lib/python3.10/dist-packages/IPython/core/ultratb.py\", line 281, in _fixed_getinnerframes\n","    records = fix_frame_records_filenames(inspect.getinnerframes(etb, context))\n","  File \"/usr/lib/python3.10/inspect.py\", line 1662, in getinnerframes\n","    frameinfo = (tb.tb_frame,) + getframeinfo(tb, context)\n","  File \"/usr/lib/python3.10/inspect.py\", line 1620, in getframeinfo\n","    filename = getsourcefile(frame) or getfile(frame)\n","  File \"/usr/lib/python3.10/inspect.py\", line 829, in getsourcefile\n","    module = getmodule(object, filename)\n","  File \"/usr/lib/python3.10/inspect.py\", line 861, in getmodule\n","    file = getabsfile(object, _filename)\n","  File \"/usr/lib/python3.10/inspect.py\", line 845, in getabsfile\n","    return os.path.normcase(os.path.abspath(_filename))\n","  File \"/usr/lib/python3.10/posixpath.py\", line 384, in abspath\n","    cwd = os.getcwd()\n","OSError: [Errno 107] Transport endpoint is not connected\n"]}],"source":["from google.colab import drive\n","drive.mount(\"/content/drive\", force_remount=True)\n","%cd /content/drive/MyDrive/TFG_Training_T/A3\n","!python main.py"]}],"metadata":{"accelerator":"GPU","colab":{"gpuType":"T4","name":"","version":""},"kernelspec":{"display_name":"Python 3","name":"python3"},"language_info":{"name":"python"}},"nbformat":4,"nbformat_minor":0}